Workbook

Sheet 工作表1
A1: 縣市 | B1: 鄉鎮區 | C1: 村里 | D1: 發生地點 | E1: 代表地標 | F1: 溪流型態(陳天健) | G1: 年度 | H1: 事件 | I1: 發生時間 | J1: 發生次數 | K1: 再發生時間間隔 | L1: 崩塌面積_災前 | M1: 崩塌面積_災後 | N1: 崩塌率_災前 | O1: 崩塌率_災後 | P1: 地震影響 | Q1: 發生次數(排除地震) | R1: 再發生時間間隔(排除地震) | S1: 警戒基準值 (mm) | T1: 觀測雨量站站號 | U1: 觀測雨量站站名 | V1: 事件總雨量 | W1: 發生降雨強度 | X1: 有效累積雨量 | Y1: 發生3小時 | Z1: 發生6小時 | AA1: 發生12小時 | AB1: 發生24小時 | AC1: 發生1hr重現期(年) | AD1: 發生3hr重現期(年) | AE1: 發生6hr重現期(年) | AF1: 發生12hr重現期(年) | AG1: 發生24hr重現期(年) | AH1: 雨場最大1小時 | AI1: 雨場最大3小時 | AJ1: 雨場最大6小時 | AK1: 雨場前最大12小時 | AL1: 雨場最大24小時 | AM1: 雨場1hr重現期(年) | AN1: 雨場3hr重現期(年) | AO1: 雨場6hr重現期(年) | AP1: 雨場12hr重現期(年) | AQ1: 雨場24hr重現期(年) | AR1: 發生降雨延時
A2: 宜蘭縣 | B2: 南澳鄉 | C2: 碧候村 | D2: 宜縣DF146 | F2: 溪流型 | G2: 101 | H2: 蘇拉颱風 | I2: 41123.083 | J2: 1 | L2: 0.565 | M2: 5.735 | N2: 0.30146196 | O2: 3.0599723 | P2: 否 | Q2: 1 | S2: 450 | T2: C0U770 | U2: 南澳 | V2: 878.5 | W2: 74.5 | X2: 668.9 | Y2: 158 | Z2: 259 | AA2: 333 | AB2: 442.5 | AC2: 2年 | AD2: 5年 | AE2: 10年 | AF2: 5年 | AG2: 5年 | AH2: 74.5 | AI2: 178 | AJ2: 300 | AK2: 433 | AL2: 582.5 | AM2: 2年 | AN2: 10年 | AO2: 25年 | AP2: 50年 | AQ2: 50年 | AR2: 59
A3: 宜蘭縣 | B3: 南澳鄉 | C3: 碧候村 | D3: 宜縣DF146 | F3: 溪流型 | G3: 113 | H3: 凱米颱風 | I3: 45498.042 | J3: 2 | K3: 11.986187 | L3: 0 | M3: 4.67 | N3: 0 | O3: 2.4917298 | P3: 是 | S3: 400 | T3: 81U860 | U3: 金岳國小 | V3: 810 | W3: 53.5 | X3: 742.2 | Y3: 82.5 | Z3: 133 | AA3: 519.5 | AB3: 707 | AC3: <2 | AD3: <2 | AE3: <2 | AF3: 200年 | AG3: 200年 | AH3: 95.5 | AI3: 266 | AJ3: 392 | AK3: 524 | AL3: 707 | AM3: 10年 | AN3: 200年 | AO3: 200年 | AP3: 200年 | AQ3: 200年 | AR3: 39
A4: 臺中市 | B4: 和平區 | C4: 博愛里 | D4: 中市DF027 | E4: 松鶴部落 | F4: 溪流型 | G4: 93 | H4: 敏督利颱風 | I4: 2004/07/02 | J4: 1 | L4: 2.8 | M4: 2.87 | N4: 5.9944337 | O4: 6.1442946 | P4: 是 | S4: 200 | T4: C1F870 | U4: 上谷關 | V4: 1337 | W4: 93 | X4: 612.1 | Y4: 147 | Z4: 221 | AA4: 297.5 | AB4: 556.5 | AC4: 10年 | AD4: 2年 | AE4: 2年 | AF4: 2年 | AG4: 25年 | AH4: 93 | AI4: 192 | AJ4: 270.5 | AK4: 395 | AL4: 600.5 | AM4: 10年 | AN4: 10年 | AO4: 10年 | AP4: 10年 | AQ4: 50年 | AR4: 24
A5: 臺中市 | B5: 和平區 | C5: 博愛里 | D5: 中市DF027 | E5: 松鶴部落 | F5: 溪流型 | G5: 94 | H5: 馬莎颱風 | I5: 38569.375 | J5: 2 | K5: 1.0941781 | L5: 2.87 | M5: 0.9 | N5: 6.1442946 | O5: 1.9267823 | P5: 否 | Q5: 1 | S5: 300 | T5: C1F870 | U5: 上谷關 | V5: 1055.5 | W5: 27 | X5: 615 | Y5: 86.5 | Z5: 220 | AA5: 431 | AB5: 615 | AC5: <2 | AD5: <2 | AE5: 2年 | AF5: 25年 | AG5: 50年 | AH5: 78 | AI5: 164 | AJ5: 295 | AK5: 450.5 | AL5: 642 | AM5: 2年 | AN5: 5年 | AO5: 25年 | AP5: 50年 | AQ5: 50年 | AR5: 24
A6: 臺中市 | B6: 和平區 | C6: 博愛里 | D6: 中市DF028 | E6: 松鶴部落 | F6: 溪流型 | G6: 93 | H6: 敏督利颱風 | I6: 2004/07/02 | J6: 1 | L6: 18.15 | M6: 13.34 | N6: 5.3974485 | O6: 3.9670503 | P6: 是 | S6: 200 | T6: C1F870 | U6: 上谷關 | V6: 1337 | W6: 93 | X6: 612.1 | Y6: 147 | Z6: 221 | AA6: 297.5 | AB6: 556.5 | AC6: 10年 | AD6: 2年 | AE6: 2年 | AF6: 2年 | AG6: 25年 | AH6: 93 | AI6: 192 | AJ6: 270.5 | AK6: 395 | AL6: 600.5 | AM6: 10年 | AN6: 10年 | AO6: 10年 | AP6: 10年 | AQ6: 50年 | AR6: 24
A7: 臺中市 | B7: 和平區 | C7: 博愛里 | D7: 中市DF028 | E7: 松鶴部落 | F7: 溪流型 | G7: 94 | H7: 馬莎颱風 | I7: 38569.417 | J7: 2 | K7: 1.0942922 | L7: 3.45 | M7: 1.72 | N7: 1.0259613 | O7: 0.51149374 | P7: 否 | Q7: 1 | S7: 300 | T7: C1F870 | U7: 上谷關 | V7: 1055.5 | W7: 27 | X7: 642 | Y7: 83 | Z7: 208 | AA7: 450 | AB7: 636 | AC7: <2 | AD7: <2 | AE7: 2年 | AF7: 50年 | AG7: 50年 | AH7: 78 | AI7: 164 | AJ7: 295 | AK7: 450.5 | AL7: 642 | AM7: 2年 | AN7: 5年 | AO7: 25年 | AP7: 50年 | AQ7: 50年 | AR7: 25
A8: 南投縣 | B8: 仁愛鄉 | C8: 南豐村 | D8: 投縣DF011 | F8: 溪流型 | G8: 90 | H8: 桃芝颱風 | I8: 37102 | J8: 1 | L8: 0 | M8: 4.7807971 | N8: 0 | O8: 8.0539035 | P8: 是 | S8: - | T8: C1H870 | U8: 仁愛 | V8: 342 | W8: 87.5 | X8: 242.5 | Y8: 106 | Z8: 173.5 | AA8: 237.5 | AB8: 237.5 | AC8: 10年 | AD8: <2 | AE8: <2 | AF8: <2 | AG8: <2 | AH8: 87.5 | AI8: 150 | AJ8: 183 | AK8: 287 | AL8: 342 | AM8: 10年 | AN8: 2年 | AO8: 2年 | AP8: 2年 | AQ8: 2年 | AR8: 12
A9: 南投縣 | B9: 仁愛鄉 | C9: 南豐村 | D9: 投縣DF011 | F9: 溪流型 | G9: 93 | H9: 敏督利颱風 | I9: 38171 | J9: 2 | K9: 2.9287671 | L9: 1.17 | M9: 0.351639 | N9: 1.9710243 | O9: 0.59238376 | P9: 是 | S9: 200 | T9: C1H870 | U9: 仁愛 | V9: 507 | W9: 55.5 | X9: 407.5 | Y9: 111.5 | Z9: 159.5 | AA9: 198 | AB9: 366 | AC9: <2 | AD9: <2 | AE9: <2 | AF9: <2 | AG9: 2年 | AH9: 55.5 | AI9: 111.5 | AJ9: 159.5 | AK9: 257 | AL9: 366 | AM9: <2 | AN9: <2 | AO9: <2 | AP9: 2年 | AQ9: 2年 | AR9: 25
A10: 南投縣 | B10: 仁愛鄉 | C10: 南豐村 | D10: 投縣DF011 | F10: 溪流型 | G10: 97 | H10: 辛樂克颱風 | I10: 39706.208 | J10: 3 | K10: 4.2060502 | L10: 0 | M10: 0 | N10: 0 | O10: 0 | P10: 否 | Q10: 1 | S10: 250 | T10: C1I330 | U10: 楓樹林 | V10: 1211 | W10: 44.5 | X10: 737.4 | Y10: 104 | Z10: 157.5 | AA10: 264 | AB10: 640 | AC10: <2 | AD10: <2 | AE10: <2 | AF10: 2年 | AG10: 50年 | AH10: 69.5 | AI10: 186 | AJ10: 341 | AK10: 582.5 | AL10: 838.5 | AM10: 2年 | AN10: 10年 | AO10: 100年 | AP10: 200年 | AQ10: 200年 | AR10: 35
A11: 南投縣 | B11: 仁愛鄉 | C11: 南豐村 | D11: 投縣DF011 | F11: 溪流型 | G11: 112 | H11: 卡努颱風 | I11: 45142.708 | J11: 4 | K11: 14.894521 | L11: 0 | M11: 0.3 | N11: 0 | O11: 0.50539084 | P11: 否 | Q11: 2 | R11: 14.894521 | S11: 300 | T11: 88H890 | U11: 南豐 | V11: 864 | W11: 112 | X11: 782 | Y11: 225 | Z11: 384 | AA11: 542 | AB11: 783.5 | AC11: 100年 | AD11: 100年 | AE11: 200年 | AF11: 200年 | AG11: 200年 | AH11: 112.5 | AI11: 225 | AJ11: 384 | AK11: 542 | AL11: 783.5 | AM11: 100年 | AN11: 100年 | AO11: 200年 | AP11: 200年 | AQ11: 200年 | AR11: 39
A12: 南投縣 | B12: 仁愛鄉 | C12: 南豐村 | D12: 投縣DF013 | E12: 聖本篤加油站 | F12: 溪流型 | G12: 90 | H12: 桃芝颱風 | I12: 37102 | J12: 1 | L12: 1.35 | M12: 3.43 | N12: 1.1721803 | O12: 2.9782061 | P12: 是 | S12: - | T12: C1H870 | U12: 仁愛 | V12: 342 | W12: 87.5 | X12: 242.5 | Y12: 106 | Z12: 173.5 | AA12: 237.5 | AB12: 237.5 | AC12: 10年 | AD12: <2 | AE12: <2 | AF12: <2 | AG12: <2 | AH12: 87.5 | AI12: 150 | AJ12: 183 | AK12: 287 | AL12: 342 | AM12: 10年 | AN12: 2年 | AO12: 2年 | AP12: 2年 | AQ12: 2年 | AR12: 12
A13: 南投縣 | B13: 仁愛鄉 | C13: 南豐村 | D13: 投縣DF013 | E13: 聖本篤加油站 | F13: 溪流型 | G13: 93 | H13: 敏督利颱風 | I13: 38171 | J13: 2 | K13: 2.9287671 | L13: 1.16 | M13: 0 | N13: 1.0072067 | O13: 0 | P13: 是 | S13: 200 | T13: C1H870 | U13: 仁愛 | V13: 507 | W13: 55.5 | X13: 407.5 | Y13: 111.5 | Z13: 159.5 | AA13: 198 | AB13: 366 | AC13: <2 | AD13: <2 | AE13: <2 | AF13: <2 | AG13: 2年 | AH13: 55.5 | AI13: 111.5 | AJ13: 159.5 | AK13: 257 | AL13: 366 | AM13: <2 | AN13: <2 | AO13: <2 | AP13: 2年 | AQ13: 2年 | AR13: 25
A14: 南投縣 | B14: 仁愛鄉 | C14: 南豐村 | D14: 投縣DF013 | E14: 聖本篤加油站 | F14: 溪流型 | G14: 97 | H14: 辛樂克颱風 | I14: 39706.333 | J14: 3 | K14: 4.2063927 | L14: 0 | M14: 0.27 | N14: 0 | O14: 0.23443605 | P14: 否 | Q14: 1 | S14: 300 | T14: C1I330 | U14: 楓樹林 | V14: 1211 | W14: 55.5 | X14: 917.8 | Y14: 186 | Z14: 290 | AA14: 377 | AB14: 762 | AC14: <2 | AD14: 10年 | AE14: 25年 | AF14: 10年 | AG14: 200年 | AH14: 69.5 | AI14: 186 | AJ14: 341 | AK14: 582.5 | AL14: 838.5 | AM14: 2年 | AN14: 10年 | AO14: 100年 | AP14: 200年 | AQ14: 200年 | AR14: 38
A15: 南投縣 | B15: 仁愛鄉 | C15: 南豐村 | D15: 投縣DF013 | E15: 聖本篤加油站 | F15: 溪流型 | G15: 112 | H15: 卡努颱風 | I15: 45142.625 | J15: 4 | K15: 14.89395 | L15: 0 | M15: 0 | N15: 0 | O15: 0 | P15: 否 | Q15: 2 | R15: 14.89395 | S15: 300 | T15: 88H890 | U15: 南豐 | V15: 864 | W15: 49 | X15: 648 | Y15: 115 | Z15: 260.5 | AA15: 425.5 | AB15: 628 | AC15: <2 | AD15: <2 | AE15: 25年 | AF15: 100年 | AG15: 200年 | AH15: 112.5 | AI15: 225 | AJ15: 384 | AK15: 542 | AL15: 783.5 | AM15: 100年 | AN15: 100年 | AO15: 200年 | AP15: 200年 | AQ15: 200年 | AR15: 37
A16: 南投縣 | B16: 仁愛鄉 | C16: 春陽村 | D16: 投縣DF030 | F16: 溪流型 | G16: 94 | H16: 海棠颱風 | I16: 38552.833 | J16: 1 | L16: 0 | M16: 0 | N16: 0 | O16: 0 | P16: 否 | Q16: 1 | S16: 300 | T16: C0I010 | U16: 廬山 | V16: 580 | W16: 48.5 | X16: 251.4 | Y16: 78 | Z16: 105.5 | AA16: 158 | AB16: 229.5 | AC16: <2 | AD16: <2 | AE16: <2 | AF16: <2 | AG16: <2 | AH16: 48.5 | AI16: 78 | AJ16: 105.5 | AK16: 158 | AL16: 278.5 | AM16: <2 | AN16: <2 | AO16: <2 | AP16: <2 | AQ16: <2 | AR16: 29
A17: 南投縣 | B17: 仁愛鄉 | C17: 春陽村 | D17: 投縣DF030 | F17: 溪流型 | G17: 112 | H17: 卡努颱風 | I17: 45143.417 | J17: 2 | K17: 18.056393 | L17: 0 | M17: 0.12 | N17: 0 | O17: 0.12039731 | P17: 否 | Q17: 2 | R17: 18.056393 | S17: 300 | T17: C0I010 | U17: 廬山 | V17: 792.5 | W17: 6 | X17: 695 | Y17: 34.5 | Z17: 34.5 | AA17: 46 | AB17: 445 | AC17: <2 | AD17: <2 | AE17: <2 | AF17: <2 | AG17: 5年 | AH17: 89.5 | AI17: 247 | AJ17: 334.5 | AK17: 529.5 | AL17: 710 | AM17: 10年 | AN17: 100年 | AO17: 100年 | AP17: 200年 | AQ17: 200年 | AR17: 42
A18: 南投縣 | B18: 水里鄉 | C18: 興隆村 | D18: 投縣DF163 | E18: 南興橋 | F18: 溪流型 | G18: 85 | H18: 賀伯颱風 | I18: 35277 | J18: 1 | L18: 0.64 | M18: 7.79 | N18: 0.58055152 | O18: 7.0664006 | P18: 否 | Q18: 1 | S18: - | T18: C1I080 | U18: 信義 | V18: 803 | W18: 71 | X18: 489.9 | Y18: 157 | Z18: 248.5 | AA18: 341 | AB18: 408.5 | AC18: 2年 | AD18: 10年 | AE18: 25年 | AF18: 25年 | AG18: 10年 | AH18: 71 | AI18: 211.5 | AJ18: 386 | AK18: 587 | AL18: 754 | AM18: 2年 | AN18: 100年 | AO18: 200年 | AP18: 200年 | AQ18: 200年 | AR18: 19
A19: 南投縣 | B19: 水里鄉 | C19: 興隆村 | D19: 投縣DF163 | E19: 南興橋 | F19: 溪流型 | G19: 90 | H19: 桃芝颱風 | I19: 37102 | J19: 2 | K19: 5 | L19: 33.58 | M19: 22.55 | N19: 30.460813 | O19: 20.45537 | P19: 是 | S19: - | T19: C1I160 | U19: 龍神橋 | V19: 485.5 | W19: 130.5 | X19: 306.4 | Y19: 246 | Z19: 265 | AA19: 297.5 | AB19: 297.5 | AC19: 200年 | AD19: 200年 | AE19: 25年 | AF19: 5年 | AG19: 2年 | AH19: 130.5 | AI19: 285.5 | AJ19: 403 | AK19: 454.5 | AL19: 485.5 | AM19: 200年 | AN19: 200年 | AO19: 200年 | AP19: 200年 | AQ19: 25年 | AR19: 9
A20: 南投縣 | B20: 水里鄉 | C20: 上安村 | D20: 投縣DF165 | E20: 三部坑溪 | F20: 溪流型 | G20: 85 | H20: 賀伯颱風 | I20: 35277 | J20: 1 | L20: 4.57 | M20: 2.72 | N20: 1.342696 | O20: 0.79915384 | P20: 否 | Q20: 1 | S20: - | T20: C1I080 | U20: 信義 | V20: 803 | W20: 71 | X20: 489.9 | Y20: 157 | Z20: 248.5 | AA20: 341 | AB20: 408.5 | AC20: 2年 | AD20: 10年 | AE20: 25年 | AF20: 25年 | AG20: 10年 | AH20: 71 | AI20: 211.5 | AJ20: 386 | AK20: 587 | AL20: 754 | AM20: 2年 | AN20: 100年 | AO20: 200年 | AP20: 200年 | AQ20: 200年 | AR20: 19
A21: 南投縣 | B21: 水里鄉 | C21: 上安村 | D21: 投縣DF165 | E21: 三部坑溪 | F21: 溪流型 | G21: 90 | H21: 桃芝颱風 | I21: 37102 | J21: 2 | K21: 5 | L21: 0.07 | M21: 59.499483 | N21: 0.020566459 | O21: 17.481338 | P21: 是 | S21: - | T21: C1I160 | U21: 龍神橋 | V21: 485.5 | W21: 130.5 | X21: 306.4 | Y21: 246 | Z21: 265 | AA21: 297.5 | AB21: 297.5 | AC21: 200年 | AD21: 200年 | AE21: 25年 | AF21: 5年 | AG21: 2年 | AH21: 130.5 | AI21: 285.5 | AJ21: 403 | AK21: 454.5 | AL21: 485.5 | AM21: 200年 | AN21: 200年 | AO21: 200年 | AP21: 200年 | AQ21: 25年 | AR21: 9
A22: 南投縣 | B22: 水里鄉 | C22: 上安村 | D22: 投縣DF165 | E22: 三部坑溪 | F22: 溪流型 | G22: 94 | H22: 馬莎颱風 | I22: 38569.5 | J22: 3 | K22: 4.0205479 | L22: 1.79 | M22: 1.63 | N22: 0.52591374 | O22: 0.47890469 | P22: 否 | Q22: 1 | S22: 300 | T22: C1I160 | U22: 龍神橋 | V22: 321 | W22: 2.5 | X22: 323.5 | Y22: 2.5 | Z22: 45 | AA22: 81 | AB22: 291 | AC22: <2 | AD22: <2 | AE22: <2 | AF22: <2 | AG22: <2 | AH22: 50.5 | AI22: 96.5 | AJ22: 149.5 | AK22: 223.5 | AL22: 321 | AM22: <2 | AN22: <2 | AO22: <2 | AP22: <2 | AQ22: 2年 | AR22: 23
A23: 南投縣 | B23: 水里鄉 | C23: 上安村 | D23: 投縣DF165 | E23: 三部坑溪 | F23: 溪流型 | G23: 95 | H23: 0609豪雨 | I23: 38878.5 | J23: 4 | K23: 0.84657534 | L23: 1.63 | M23: 5 | N23: 0.47890469 | O23: 1.4690328 | P23: 否 | Q23: 2 | R23: 0.84657534 | S23: 200 | T23: C1I160 | U23: 龍神橋 | V23: 445.5 | W23: 3.5 | X23: 401.6 | Y23: 24 | Z23: 93 | AA23: 138 | AB23: 263 | AC23: <2 | AD23: <2 | AE23: <2 | AF23: <2 | AG23: <2 | AH23: 41 | AI23: 83 | AJ23: 139 | AK23: 196.5 | AL23: 309 | AM23: <2 | AN23: <2 | AO23: <2 | AP23: <2 | AQ23: 2年 | AR23: 33
A24: 南投縣 | B24: 水里鄉 | C24: 郡坑村 | D24: 投縣DF167 | E24: 二部坑溪 | F24: 溪流型 | G24: 85 | H24: 賀伯颱風 | I24: 35277 | J24: 1 | L24: 0.42 | M24: 0.06 | N24: 0.61046512 | O24: 0.087209302 | P24: 否 | Q24: 1 | S24: - | T24: C1I080 | U24: 信義 | V24: 803 | W24: 71 | X24: 489.9 | Y24: 157 | Z24: 248.5 | AA24: 341 | AB24: 408.5 | AC24: 2年 | AD24: 10年 | AE24: 25年 | AF24: 25年 | AG24: 10年 | AH24: 71 | AI24: 211.5 | AJ24: 386 | AK24: 587 | AL24: 754 | AM24: 2年 | AN24: 100年 | AO24: 200年 | AP24: 200年 | AQ24: 200年 | AR24: 19
A25: 南投縣 | B25: 水里鄉 | C25: 郡坑村 | D25: 投縣DF167 | E25: 二部坑溪 | F25: 溪流型 | G25: 90 | H25: 桃芝颱風 | I25: 37102 | J25: 2 | K25: 5 | L25: 1.83 | M25: 15.03 | N25: 2.6598837 | O25: 21.84593 | P25: 是 | S25: - | T25: C1I160 | U25: 龍神橋 | V25: 485.5 | W25: 130.5 | X25: 306.4 | Y25: 246 | Z25: 265 | AA25: 297.5 | AB25: 297.5 | AC25: 200年 | AD25: 200年 | AE25: 25年 | AF25: 5年 | AG25: 2年 | AH25: 130.5 | AI25: 285.5 | AJ25: 403 | AK25: 454.5 | AL25: 485.5 | AM25: 200年 | AN25: 200年 | AO25: 200年 | AP25: 200年 | AQ25: 25年 | AR25: 9
A26: 南投縣 | B26: 水里鄉 | C26: 新山村 | D26: 投縣DF169 | E26: 新安橋(南平坑) | F26: 溪流型 | G26: 85 | H26: 賀伯颱風 | I26: 35278.083 | J26: 1 | L26: 3.5 | M26: 2.02 | N26: 2.6229017 | O26: 1.513789 | P26: 否 | Q26: 1 | S26: - | T26: C1I080 | U26: 信義 | V26: 803 | W26: 71 | X26: 489.9 | Y26: 157 | Z26: 248.5 | AA26: 341 | AB26: 408.5 | AC26: 2年 | AD26: 10年 | AE26: 25年 | AF26: 25年 | AG26: 10年 | AH26: 71 | AI26: 211.5 | AJ26: 386 | AK26: 587 | AL26: 754 | AM26: 2年 | AN26: 100年 | AO26: 200年 | AP26: 200年 | AQ26: 200年 | AR26: 19
A27: 南投縣 | B27: 水里鄉 | C27: 新山村 | D27: 投縣DF169 | E27: 新安橋(南平坑) | F27: 溪流型 | G27: 90 | H27: 桃芝颱風 | I27: 37102 | J27: 2 | K27: 4.997032 | L27: 4.26 | M27: 20.703212 | N27: 3.192446 | O27: 15.514997 | P27: 是 | S27: - | T27: C1I160 | U27: 龍神橋 | V27: 485.5 | W27: 130.5 | X27: 306.4 | Y27: 246 | Z27: 265 | AA27: 297.5 | AB27: 297.5 | AC27: 200年 | AD27: 200年 | AE27: 25年 | AF27: 5年 | AG27: 2年 | AH27: 130.5 | AI27: 285.5 | AJ27: 403 | AK27: 454.5 | AL27: 485.5 | AM27: 200年 | AN27: 200年 | AO27: 200年 | AP27: 200年 | AQ27: 25年 | AR27: 9
A28: 南投縣 | B28: 水里鄉 | C28: 新山村 | D28: 投縣DF170 | F28: 溪流型 | G28: 85 | H28: 賀伯颱風 | I28: 35278.083 | J28: 1 | L28: 1.08 | M28: 0.37 | N28: 1.2746371 | O28: 0.43668122 | P28: 否 | Q28: 1 | S28: - | T28: C1I080 | U28: 信義 | V28: 803 | W28: 71 | X28: 489.9 | Y28: 157 | Z28: 248.5 | AA28: 341 | AB28: 408.5 | AC28: 2年 | AD28: 10年 | AE28: 25年 | AF28: 25年 | AG28: 10年 | AH28: 71 | AI28: 211.5 | AJ28: 386 | AK28: 587 | AL28: 754 | AM28: 2年 | AN28: 100年 | AO28: 200年 | AP28: 200年 | AQ28: 200年 | AR28: 19
A29: 南投縣 | B29: 水里鄉 | C29: 新山村 | D29: 投縣DF170 | F29: 溪流型 | G29: 90 | H29: 桃芝颱風 | I29: 37102 | J29: 2 | K29: 4.997032 | L29: 0.48 | M29: 8.085844 | N29: 0.56650537 | O29: 9.543071 | P29: 是 | S29: - | T29: C1I160 | U29: 龍神橋 | V29: 485.5 | W29: 130.5 | X29: 306.4 | Y29: 246 | Z29: 265 | AA29: 297.5 | AB29: 297.5 | AC29: 200年 | AD29: 200年 | AE29: 25年 | AF29: 5年 | AG29: 2年 | AH29: 130.5 | AI29: 285.5 | AJ29: 403 | AK29: 454.5 | AL29: 485.5 | AM29: 200年 | AN29: 200年 | AO29: 200年 | AP29: 200年 | AQ29: 25年 | AR29: 9
A30: 南投縣 | B30: 信義鄉 | C30: 潭南村 | D30: 投縣DF178 | E30: 潭南一號橋 | F30: 溪流型 | G30: 90 | H30: 桃芝颱風 | I30: 37102.25 | J30: 1 | L30: 3.7 | M30: 5.8128247 | N30: 0.92571743 | O30: 1.4543333 | P30: 是 | S30: - | T30: C1I150 | U30: 青雲 | V30: 459.5 | W30: 100.5 | X30: 284.8 | Y30: 185 | Z30: 228.5 | AA30: 265.5 | AB30: 265.5 | AC30: 25年 | AD30: 25年 | AE30: 10年 | AF30: 2年 | AG30: <2 | AH30: 100.5 | AI30: 251 | AJ30: 340 | AK30: 420 | AL30: 459.5 | AM30: 25年 | AN30: 200年 | AO30: 200年 | AP30: 50年 | AQ30: 10年 | AR30: 9
A31: 南投縣 | B31: 信義鄉 | C31: 潭南村 | D31: 投縣DF178 | E31: 潭南一號橋 | F31: 溪流型 | G31: 97 | H31: 卡玫基颱風 | I31: 39647.083 | J31: 2 | K31: 6.9721461 | L31: 0 | M31: 2.04 | N31: 0 | O31: 0.51039556 | P31: 否 | Q31: 1 | S31: 250 | T31: C1I150 | U31: 青雲 | V31: 404 | W31: 109 | X31: 272.6 | Y31: 212.5 | Z31: 234 | AA31: 242 | AB31: 242 | AC31: 50年 | AD31: 50年 | AE31: 10年 | AF31: 2年 | AG31: <2 | AH31: 108 | AI31: 222.5 | AJ31: 309 | AK31: 376 | AL31: 404 | AM31: 50年 | AN31: 100年 | AO31: 50年 | AP31: 25年 | AQ31: 5年 | AR31: 11
A32: 南投縣 | B32: 信義鄉 | C32: 明德村 | D32: 投縣DF187 | F32: 坡面型 | G32: 90 | H32: 桃芝颱風 | I32: 37102.292 | J32: 1 | L32: 0 | M32: 0 | N32: 0 | O32: 0 | P32: 是 | S32: - | T32: C1I080 | U32: 信義 | V32: 465 | W32: 125.5 | X32: 340.9 | Y32: 129.5 | Z32: 146.5 | AA32: 182 | AB32: 182 | AC32: 200年 | AD32: 2年 | AE32: <2 | AF32: <2 | AG32: <2 | AH32: 125.5 | AI32: 244 | AJ32: 368 | AK32: 429.5 | AL32: 465 | AM32: 200年 | AN32: 200年 | AO32: 200年 | AP32: 200年 | AQ32: 25年 | AR32: 9
A33: 南投縣 | B33: 信義鄉 | C33: 明德村 | D33: 投縣DF187 | F33: 坡面型 | G33: 113 | H33: 凱米颱風 | I33: 45498.125 | J33: 2 | K33: 23.002283 | L33: 0 | M33: 0 | N33: 0 | O33: 0 | P33: 否 | Q33: 1 | S33: 300 | T33: C0I080 | U33: 信義 | V33: 613.5 | W33: 52.5 | X33: 336.5 | Y33: 148 | Z33: 193.5 | AA33: 297 | AB33: 337.5 | AC33: <2 | AD33: 5年 | AE33: 5年 | AF33: 10年 | AG33: 2年 | AH33: 53 | AI33: 148.5 | AJ33: 231 | AK33: 332.5 | AL33: 526.5 | AM33: <2 | AN33: 5年 | AO33: 10年 | AP33: 25年 | AQ33: 100年 | AR33: 38
A34: 南投縣 | B34: 信義鄉 | C34: 豐丘村 | D34: 投縣DF189 | E34: 豐丘明隧道 | F34: 溪流型 | G34: 85 | H34: 賀伯颱風 | I34: 35278.042 | J34: 1 | L34: 0.43 | M34: 2.33 | N34: 0.22916223 | O34: 1.2417395 | P34: 否 | Q34: 1 | S34: - | T34: C1I080 | U34: 信義 | V34: 803 | W34: 71 | X34: 489.9 | Y34: 157 | Z34: 248.5 | AA34: 341 | AB34: 408.5 | AC34: 2年 | AD34: 10年 | AE34: 25年 | AF34: 25年 | AG34: 10年 | AH34: 71 | AI34: 211.5 | AJ34: 386 | AK34: 587 | AL34: 754 | AM34: 2年 | AN34: 100年 | AO34: 200年 | AP34: 200年 | AQ34: 200年 | AR34: 19
A35: 南投縣 | B35: 信義鄉 | C35: 豐丘村 | D35: 投縣DF189 | E35: 豐丘明隧道 | F35: 溪流型 | G35: 90 | H35: 桃芝颱風 | I35: 37102 | J35: 2 | K35: 4.9971461 | L35: 0 | M35: 4.0253106 | N35: 0 | O35: 2.1452305 | P35: 是 | S35: - | T35: C1I080 | U35: 信義 | V35: 465 | W35: 125.5 | X35: 340.9 | Y35: 129.5 | Z35: 146.5 | AA35: 182 | AB35: 182 | AC35: 200年 | AD35: 2年 | AE35: <2 | AF35: <2 | AG35: <2 | AH35: 125.5 | AI35: 244 | AJ35: 368 | AK35: 429.5 | AL35: 465 | AM35: 200年 | AN35: 200年 | AO35: 200年 | AP35: 200年 | AQ35: 25年 | AR35: 9
A36: 南投縣 | B36: 信義鄉 | C36: 豐丘村 | D36: 投縣DF189 | E36: 豐丘明隧道 | F36: 溪流型 | G36: 97 | H36: 辛樂克颱風 | I36: 39706.792 | J36: 3 | K36: 7.1364155 | L36: 0.84 | M36: 0.58 | N36: 0.44766574 | O36: 0.30910254 | P36: 否 | Q36: 1 | S36: 250 | T36: C1I080 | U36: 信義 | V36: 598 | W36: 2.5 | X36: 552.5 | Y36: 6 | Z36: 12 | AA36: 30.5 | AB36: 30.5 | AC36: <2 | AD36: <2 | AE36: <2 | AF36: <2 | AG36: <2 | AH36: 43 | AI36: 118 | AJ36: 197 | AK36: 296.5 | AL36: 475 | AM36: <2 | AN36: 2年 | AO36: 5年 | AP36: 10年 | AQ36: 25年 | AR36: 38
A37: 南投縣 | B37: 信義鄉 | C37: 豐丘村 | D37: 投縣DF190 | E37: 豐丘 | F37: 溪流型 | G37: 85 | H37: 賀伯颱風 | I37: 35278 | J37: 1 | L37: 0.33 | M37: 0.18 | N37: 0.20521112 | O37: 0.21176471 | P37: 否 | Q37: 1 | S37: - | T37: C1I080 | U37: 信義 | V37: 803 | W37: 71 | X37: 489.9 | Y37: 157 | Z37: 248.5 | AA37: 341 | AB37: 408.5 | AC37: 2年 | AD37: 10年 | AE37: 25年 | AF37: 25年 | AG37: 10年 | AH37: 71 | AI37: 211.5 | AJ37: 386 | AK37: 587 | AL37: 754 | AM37: 2年 | AN37: 100年 | AO37: 200年 | AP37: 200年 | AQ37: 200年 | AR37: 19
A38: 南投縣 | B38: 信義鄉 | C38: 豐丘村 | D38: 投縣DF190 | E38: 豐丘 | F38: 溪流型 | G38: 90 | H38: 桃芝颱風 | I38: 37102 | J38: 2 | K38: 4.9972603 | L38: 0 | M38: 8.4433681 | N38: 0 | O38: 9.3815202 | P38: 是 | S38: - | T38: C1I080 | U38: 信義 | V38: 465 | W38: 125.5 | X38: 340.9 | Y38: 129.5 | Z38: 146.5 | AA38: 182 | AB38: 182 | AC38: 200年 | AD38: 2年 | AE38: <2 | AF38: <2 | AG38: <2 | AH38: 125.5 | AI38: 244 | AJ38: 368 | AK38: 429.5 | AL38: 465 | AM38: 200年 | AN38: 200年 | AO38: 200年 | AP38: 200年 | AQ38: 25年 | AR38: 9
A39: 南投縣 | B39: 信義鄉 | C39: 豐丘村 | D39: 投縣DF190 | E39: 豐丘 | F39: 溪流型 | G39: 101 | H39: 0504豪雨 | I39: 41032.667 | J39: 3 | K39: 10.76895 | L39: 1.62 | M39: 2.13 | N39: 1.0074 | O39: 1.3245445 | P39: 否 | Q39: 1 | S39: 250 | T39: C1I290 | U39: 豐丘 | V39: 138 | W39: 38.5 | X39: 121.4 | Y39: 92 | Z39: 138 | AA39: 138 | AB39: 138 | AC39: <2 | AD39: <2 | AE39: <2 | AF39: <2 | AG39: <2 | AH39: 46.5 | AI39: 92 | AJ39: 138 | AK39: 138 | AL39: 138 | AM39: <2 | AN39: <2 | AO39: <2 | AP39: <2 | AQ39: <2 | AR39: 138
A40: 南投縣 | B40: 信義鄉 | C40: 豐丘村 | D40: 投縣DF191 | F40: 溪流型 | G40: 85 | H40: 賀伯颱風 | I40: 35277.458 | J40: 1 | L40: 0.06 | M40: 0.91 | N40: 0.033370412 | O40: 0.50611791 | P40: 否 | Q40: 1 | S40: - | T40: C1I080 | U40: 信義 | V40: 803 | W40: 71 | X40: 489.9 | Y40: 157 | Z40: 248.5 | AA40: 341 | AB40: 408.5 | AC40: 2年 | AD40: 10年 | AE40: 25年 | AF40: 25年 | AG40: 10年 | AH40: 71 | AI40: 211.5 | AJ40: 386 | AK40: 587 | AL40: 754 | AM40: 2年 | AN40: 100年 | AO40: 200年 | AP40: 200年 | AQ40: 200年 | AR40: 19
...

Sheet 水保局全省災害資料
A1: 序號 | B1: 類型 | C1: 災害案件編號 | D1: 災區位置 | E1: 縣市 | F1: 鄉區 | G1: 村里 | H1: 溪流名稱或編號 | I1: X_TWD97 | J1: Y_TWD97 | K1: X_TWD67 | L1: Y_TWD67 | M1: 年度 | N1: 觸發事件 | O1: 災害發生時間 | P1: 災情描述 | Q1: 備註 | R1: 觀測雨量站站號 | S1: 觀測雨量站站名 | T1: 降雨強度 (mm/hr) | U1: 有效累積雨量 (mm) | V1: 警戒基準值 (mm) | W1: 判斷 | X1: 崩塌面積(ha) | Y1: 崩塌量體(立方) | Z1: 堆積土方量(立方) | AA1: 1小時累積雨量 | AB1: 3小時累積雨量 | AC1: 比對狀態
A2: 1 | B2: 土石流 | E2: 新竹縣 | F2: 尖石鄉 | G2: 嘉樂村 | H2: 竹縣DF054 | I2: 271720.83 | J2: 2734987.9 | K2: 270892 | L2: 2735194 | M2: 93 | N2: 0910水災暨海馬颱風 | O2: 2004/09/11 | Q2: 無明確座標登錄以溪流溢流點座標代表 | W2: =IF(IF(ISERROR(SEARCH("-",P2))=TRUE,0,1)=1,IF(H2<>"",0,1),0) -> 0 | AC2: =IF(COUNTIFS(作業區!$W$2:$W$2000, T2, 作業區!$X$2:$X$2000, U2)>0, "已存在", "未擴充") -> 已存在
A3: =ROW(A3)-1 -> 2 | B3: 土石流 | E3: 新竹縣 | F3: 五峰鄉 | G3: 桃山村 | M3: 93 | N3: 艾利颱風 | O3: 2004/08/25 | Q3: 民都有部落後方野溪 | W3: =IF(IF(ISERROR(SEARCH("-",P3))=TRUE,0,1)=1,IF(H3<>"",0,1),0) -> 0 | AC3: =IF(COUNTIFS(作業區!$W$2:$W$2000, T3, 作業區!$X$2:$X$2000, U3)>0, "已存在", "未擴充") -> 已存在
A4: =ROW(A4)-1 -> 3 | B4: 土石流 | E4: 新竹縣 | F4: 五峰鄉 | G4: 桃山村 | H4: 竹縣DF043 | I4: 260939.86 | J4: 2718472.9 | K4: 260111 | L4: 2718679 | M4: 93 | N4: 艾利颱風 | O4: 2004/08/25 | Q4: 無明確座標登錄以溪流溢流點座標代表 | W4: =IF(IF(ISERROR(SEARCH("-",P4))=TRUE,0,1)=1,IF(H4<>"",0,1),0) -> 0 | AC4: =IF(COUNTIFS(作業區!$W$2:$W$2000, T4, 作業區!$X$2:$X$2000, U4)>0, "已存在", "未擴充") -> 已存在
A5: =ROW(A5)-1 -> 4 | B5: 崩塌 | E5: 新竹縣 | F5: 五峰鄉 | G5: 桃山村 | H5: 竹縣DF045 | I5: 258887.87 | J5: 2717340 | K5: 258059 | L5: 2717546 | M5: 93 | N5: 艾利颱風 | O5: 2004/08/25 | Q5: 無明確座標登錄以溪流溢流點座標代表 | W5: =IF(IF(ISERROR(SEARCH("-",P5))=TRUE,0,1)=1,IF(H5<>"",0,1),0) -> 0 | AC5: =IF(COUNTIFS(作業區!$W$2:$W$2000, T5, 作業區!$X$2:$X$2000, U5)>0, "已存在", "未擴充") -> 已存在
A6: =ROW(A6)-1 -> 5 | B6: 土石流 | E6: 臺中市 | F6: 和平區 | G6: 博愛里 | H6: 中市DF028 | I6: 248606.9 | J6: 2674576.1 | K6: 247778 | L6: 2674782 | M6: 93 | N6: 敏督利暨七二水災 | O6: 2004/07/02 | Q6: 無明確座標登錄以溪流溢流點座標代表 | W6: =IF(IF(ISERROR(SEARCH("-",P6))=TRUE,0,1)=1,IF(H6<>"",0,1),0) -> 0 | AC6: =IF(COUNTIFS(作業區!$W$2:$W$2000, T6, 作業區!$X$2:$X$2000, U6)>0, "已存在", "未擴充") -> 已存在
A7: =ROW(A7)-1 -> 6 | B7: 土石流 | E7: 臺中市 | F7: 和平區 | G7: 博愛里 | H7: 中市DF027 | I7: 248031.91 | J7: 2674145.1 | K7: 247203 | L7: 2674351 | M7: 93 | N7: 敏督利暨七二水災 | O7: 2004/07/02 | Q7: 無明確座標登錄以溪流溢流點座標代表 | W7: =IF(IF(ISERROR(SEARCH("-",P7))=TRUE,0,1)=1,IF(H7<>"",0,1),0) -> 0 | AC7: =IF(COUNTIFS(作業區!$W$2:$W$2000, T7, 作業區!$X$2:$X$2000, U7)>0, "已存在", "未擴充") -> 已存在
A8: =ROW(A8)-1 -> 7 | B8: 土石流 | E8: 臺中市 | F8: 和平區 | G8: 達觀里 | H8: 中市DF008 | I8: 242428.93 | J8: 2689834 | K8: 241600 | L8: 2690040 | M8: 93 | N8: 敏督利暨七二水災 | O8: 38170.396 | Q8: 無明確座標登錄以溪流溢流點座標代表 | W8: =IF(IF(ISERROR(SEARCH("-",P8))=TRUE,0,1)=1,IF(H8<>"",0,1),0) -> 0 | AC8: =IF(COUNTIFS(作業區!$W$2:$W$2000, T8, 作業區!$X$2:$X$2000, U8)>0, "已存在", "未擴充") -> 已存在
A9: =ROW(A9)-1 -> 8 | B9: 土石流 | E9: 臺中市 | F9: 東勢區 | G9: 慶福里 | H9: 中市DF056 | I9: 235277.95 | J9: 2676033.1 | K9: 234449 | L9: 2676239 | M9: 93 | N9: 敏督利暨七二水災 | O9: 2004/07/03 | Q9: 無明確座標登錄以溪流溢流點座標代表 | W9: =IF(IF(ISERROR(SEARCH("-",P9))=TRUE,0,1)=1,IF(H9<>"",0,1),0) -> 0 | AC9: =IF(COUNTIFS(作業區!$W$2:$W$2000, T9, 作業區!$X$2:$X$2000, U9)>0, "已存在", "未擴充") -> 已存在
A10: =ROW(A10)-1 -> 9 | B10: 土石流 | E10: 南投縣 | F10: 埔里鎮 | G10: 南村里 | H10: 投縣DF035 | I10: 242588.93 | J10: 2651704.2 | K10: 241760 | L10: 2651910 | M10: 93 | N10: 敏督利暨七二水災 | O10: 2004/07/03 | Q10: 無明確座標登錄以溪流溢流點座標代表 | W10: =IF(IF(ISERROR(SEARCH("-",P10))=TRUE,0,1)=1,IF(H10<>"",0,1),0) -> 0 | AC10: =IF(COUNTIFS(作業區!$W$2:$W$2000, T10, 作業區!$X$2:$X$2000, U10)>0, "已存在", "未擴充") -> 已存在
A11: =ROW(A11)-1 -> 10 | B11: 土石流 | E11: 南投縣 | F11: 仁愛鄉 | G11: 合作村 | M11: 93 | N11: 敏督利暨七二水災 | O11: 2004/07/03 | Q11: 投85線旁新增土石流野溪 | W11: =IF(IF(ISERROR(SEARCH("-",P11))=TRUE,0,1)=1,IF(H11<>"",0,1),0) -> 0 | AC11: =IF(COUNTIFS(作業區!$W$2:$W$2000, T11, 作業區!$X$2:$X$2000, U11)>0, "已存在", "未擴充") -> 已存在
A12: =ROW(A12)-1 -> 11 | B12: 土石流 | E12: 新竹縣 | F12: 北埔鄉 | G12: 南坑村 | H12: 竹縣DF031 | I12: 255623.88 | J12: 2728776.9 | K12: 254795 | L12: 2728983 | M12: 94 | N12: 0512豪雨 | O12: 38485.083 | Q12: 無明確座標登錄以溪流溢流點座標代表 | W12: =IF(IF(ISERROR(SEARCH("-",P12))=TRUE,0,1)=1,IF(H12<>"",0,1),0) -> 0 | AC12: =IF(COUNTIFS(作業區!$W$2:$W$2000, T12, 作業區!$X$2:$X$2000, U12)>0, "已存在", "未擴充") -> 已存在
A13: =ROW(A13)-1 -> 12 | B13: 土石流 | E13: 嘉義縣 | F13: 中埔鄉 | G13: 石硦村 | H13: 嘉縣DF036 | I13: 206787.07 | J13: 2587573.4 | K13: 205958 | L13: 2587779 | M13: 94 | N13: 0612豪雨 | O13: 38518.5 | Q13: 無明確座標登錄以溪流溢流點座標代表 | W13: =IF(IF(ISERROR(SEARCH("-",P13))=TRUE,0,1)=1,IF(H13<>"",0,1),0) -> 0 | AC13: =IF(COUNTIFS(作業區!$W$2:$W$2000, T13, 作業區!$X$2:$X$2000, U13)>0, "已存在", "未擴充") -> 已存在
A14: =ROW(A14)-1 -> 13 | B14: 土石流 | E14: 南投縣 | F14: 仁愛鄉 | G14: 春陽村 | H14: 投縣DF030 | I14: 266336.84 | J14: 2658549.2 | K14: 265508 | L14: 2658755 | M14: 94 | N14: 海棠颱風 | O14: 38552.833 | Q14: 無明確座標登錄以溪流溢流點座標代表 | W14: =IF(IF(ISERROR(SEARCH("-",P14))=TRUE,0,1)=1,IF(H14<>"",0,1),0) -> 0 | AC14: =IF(COUNTIFS(作業區!$W$2:$W$2000, T14, 作業區!$X$2:$X$2000, U14)>0, "已存在", "未擴充") -> 已存在
A15: =ROW(A15)-1 -> 14 | B15: 土石流 | E15: 屏東縣 | F15: 滿洲鄉 | G15: 港口村 | H15: 屏縣DF064 | I15: 233864.98 | J15: 2432924.1 | K15: 233036 | L15: 2433129 | M15: 94 | N15: 海棠颱風 | O15: 38552.833 | Q15: 無明確座標登錄以溪流溢流點座標代表 | W15: =IF(IF(ISERROR(SEARCH("-",P15))=TRUE,0,1)=1,IF(H15<>"",0,1),0) -> 0 | AC15: =IF(COUNTIFS(作業區!$W$2:$W$2000, T15, 作業區!$X$2:$X$2000, U15)>0, "已存在", "未擴充") -> 已存在
A16: =ROW(A16)-1 -> 15 | B16: 土石流 | E16: 苗栗縣 | F16: 泰安鄉 | G16: 清安村 | H16: 苗縣DF067 | I16: 242748.92 | J16: 2703664 | K16: 241920 | L16: 2703870 | M16: 94 | N16: 海棠颱風 | O16: 38552.625 | Q16: 無明確座標登錄以溪流溢流點座標代表 | W16: =IF(IF(ISERROR(SEARCH("-",P16))=TRUE,0,1)=1,IF(H16<>"",0,1),0) -> 0 | AC16: =IF(COUNTIFS(作業區!$W$2:$W$2000, T16, 作業區!$X$2:$X$2000, U16)>0, "已存在", "未擴充") -> 已存在
A17: =ROW(A17)-1 -> 16 | B17: 土石流 | E17: 苗栗縣 | F17: 泰安鄉 | G17: 錦水村 | H17: 苗縣DF061 | I17: 242944.92 | J17: 2706199 | K17: 242116 | L17: 2706405 | M17: 94 | N17: 海棠颱風 | O17: 38552.625 | Q17: 無明確座標登錄以溪流溢流點座標代表 | W17: =IF(IF(ISERROR(SEARCH("-",P17))=TRUE,0,1)=1,IF(H17<>"",0,1),0) -> 0 | AC17: =IF(COUNTIFS(作業區!$W$2:$W$2000, T17, 作業區!$X$2:$X$2000, U17)>0, "已存在", "未擴充") -> 已存在
A18: =ROW(A18)-1 -> 17 | B18: 土石流 | E18: 苗栗縣 | F18: 泰安鄉 | G18: 八卦村 | H18: 苗縣DF059 | I18: 242223.93 | J18: 2707436 | K18: 241395 | L18: 2707642 | M18: 94 | N18: 海棠颱風 | O18: 38552.625 | Q18: 無明確座標登錄以溪流溢流點座標代表 | W18: =IF(IF(ISERROR(SEARCH("-",P18))=TRUE,0,1)=1,IF(H18<>"",0,1),0) -> 0 | AC18: =IF(COUNTIFS(作業區!$W$2:$W$2000, T18, 作業區!$X$2:$X$2000, U18)>0, "已存在", "未擴充") -> 已存在
A19: =ROW(A19)-1 -> 18 | B19: 土石流 | E19: 高雄市 | F19: 六龜區 | G19: 大津里 | H19: 高市DF050 | I19: 214011.05 | J19: 2534765.7 | K19: 213182 | L19: 2534971 | M19: 94 | N19: 海棠颱風 | O19: 38552.417 | Q19: 無明確座標登錄以溪流溢流點座標代表 | W19: =IF(IF(ISERROR(SEARCH("-",P19))=TRUE,0,1)=1,IF(H19<>"",0,1),0) -> 0 | AC19: =IF(COUNTIFS(作業區!$W$2:$W$2000, T19, 作業區!$X$2:$X$2000, U19)>0, "已存在", "未擴充") -> 已存在
A20: =ROW(A20)-1 -> 19 | B20: 土石流 | E20: 高雄市 | F20: 六龜區 | G20: 中興里 | H20: 高市DF051 | I20: 214260.05 | J20: 2538183.6 | K20: 213431 | L20: 2538389 | M20: 94 | N20: 海棠颱風 | O20: 38552.583 | Q20: 無明確座標登錄以溪流溢流點座標代表 | W20: =IF(IF(ISERROR(SEARCH("-",P20))=TRUE,0,1)=1,IF(H20<>"",0,1),0) -> 0 | AC20: =IF(COUNTIFS(作業區!$W$2:$W$2000, T20, 作業區!$X$2:$X$2000, U20)>0, "已存在", "未擴充") -> 已存在
A21: =ROW(A21)-1 -> 20 | B21: 土石流 | E21: 高雄市 | F21: 六龜區 | G21: 新發里 | H21: 高市DF055 | I21: 218694.03 | J21: 2552707.6 | K21: 217865 | L21: 2552913 | M21: 94 | N21: 海棠颱風 | O21: 38552.542 | Q21: 無明確座標登錄以溪流溢流點座標代表 | W21: =IF(IF(ISERROR(SEARCH("-",P21))=TRUE,0,1)=1,IF(H21<>"",0,1),0) -> 0 | AC21: =IF(COUNTIFS(作業區!$W$2:$W$2000, T21, 作業區!$X$2:$X$2000, U21)>0, "已存在", "未擴充") -> 已存在
A22: =ROW(A22)-1 -> 21 | B22: 土石流 | E22: 新竹縣 | F22: 尖石鄉 | G22: 玉峰村 | H22: 竹縣DF071 | I22: 280350.8 | J22: 2728275.9 | K22: 279522 | L22: 2728482 | M22: 94 | N22: 海棠颱風 | O22: 38551.208 | Q22: 無明確座標登錄以溪流溢流點座標代表 | W22: =IF(IF(ISERROR(SEARCH("-",P22))=TRUE,0,1)=1,IF(H22<>"",0,1),0) -> 0 | AC22: =IF(COUNTIFS(作業區!$W$2:$W$2000, T22, 作業區!$X$2:$X$2000, U22)>0, "已存在", "未擴充") -> 已存在
A23: =ROW(A23)-1 -> 22 | B23: 土石流 | E23: 新竹縣 | F23: 尖石鄉 | G23: 梅花村 | H23: 竹縣DF068 | I23: 269395.84 | J23: 2729557.9 | K23: 268567 | L23: 2729764 | M23: 94 | N23: 海棠颱風 | O23: 38551.208 | Q23: 無明確座標登錄以溪流溢流點座標代表 | W23: =IF(IF(ISERROR(SEARCH("-",P23))=TRUE,0,1)=1,IF(H23<>"",0,1),0) -> 0 | AC23: =IF(COUNTIFS(作業區!$W$2:$W$2000, T23, 作業區!$X$2:$X$2000, U23)>0, "已存在", "未擴充") -> 已存在
... A29: =ROW(A29)-1 -> 28 | B29: 土石流 | E29: 花蓮縣 | F29: 秀林鄉 | G29: 富世村 | H29: 花縣DF002 | I29: 295812.73 | J29: 2678125.1 | K29: 294984 | L29: 2678331 | M29: 94 | N29: 龍王颱風 | O29: 38627.542 | Q29: 無明確座標登錄以溪流溢流點座標代表 | W29: =IF(IF(ISERROR(SEARCH("-",P29))=TRUE,0,1)=1,IF(H29<>"",0,1),0) -> 0 | AC29: =IF(COUNTIFS(作業區!$W$2:$W$2000, T29, 作業區!$X$2:$X$2000, U29)>0, "已存在", "未擴充") -> 已存在
A30: =ROW(A30)-1 -> 29 | B30: 土石流 | D30: 安山三號橋 | E30: 南投縣 | F30: 水里鄉 | G30: 上安村 | H30: 投縣DF165 | I30: 236219.95 | J30: 2625277.3 | K30: 235391 | L30: 2625483 | M30: 95 | N30: 0609豪雨 | O30: 38878.5 | P30: 1.安山三號橋旁道路遭淤埋80公尺。2.右岸支流土石溢流河道，淤埋三廍巷20號前庭院及左側道路。3.支流匯流口下游河道土石堆積堵塞。4.安山三號橋孔遭土石堵塞。5.人命損失：0人 ；房舍受損：0棟。6.道路毀損：約80公尺。 | R30: C1I160 | S30: 龍神橋 | T30: 3.5 | U30: 401.6 | V30: 200 | W30: =IF(IF(ISERROR(SEARCH("-",P30))=TRUE,0,1)=1,IF(H30<>"",0,1),0) -> 0 | AC30: =IF(COUNTIFS(作業區!$W$2:$W$2000, T30, 作業區!$X$2:$X$2000, U30)>0, "已存在", "未擴充") -> 已存在
A31: =ROW(A31)-1 -> 30 | B31: 土石流 | D31: 大津靈修營地對面野溪 | E31: 高雄市 | F31: 六龜區 | G31: 大津里 | H31: 高市DF049 | I31: 214028.05 | J31: 2533857.7 | K31: 213199 | L31: 2534063 | M31: 95 | N31: 0609豪雨 | O31: 38877.75 | P31: 1.台27線旁農路遭土石淤埋約20公尺。2.台27線旁農路下方排水箱涵及排水溝遭土石堵塞。3.人命損失：0人4.房舍受損：0棟 5.道路毀損：約20公尺。6.崩塌面積 4.5ha。 | R31: C1V340 | S31: 大津 | T31: 14.4 | U31: 336.4 | V31: 400 | W31: =IF(IF(ISERROR(SEARCH("-",P31))=TRUE,0,1)=1,IF(H31<>"",0,1),0) -> 0 | AC31: =IF(COUNTIFS(作業區!$W$2:$W$2000, T31, 作業區!$X$2:$X$2000, U31)>0, "已存在", "未擴充") -> 已存在
A32: =ROW(A32)-1 -> 31 | B32: 土石流 | D32: 津鳳宮後方野溪 | E32: 高雄市 | F32: 六龜區 | G32: 大津里 | H32: 高市DF075 | I32: 213974.05 | J32: 2533634.7 | K32: 213145 | L32: 2533840 | M32: 95 | N32: 0609豪雨 | O32: 38878.25 | P32: 1.津鳳宮兩側3戶民宅遭溢流河道土石泥流侵入。2.津鳳宮後方野溪彎道處河道土石堆積堵塞。3.人命損失：0人 房舍受損：0棟。4.道路毀損：約20公尺。 | R32: C1V340 | S32: 大津 | T32: 48.5 | U32: 431.6 | V32: 400 | W32: =IF(IF(ISERROR(SEARCH("-",P32))=TRUE,0,1)=1,IF(H32<>"",0,1),0) -> 0 | AC32: =IF(COUNTIFS(作業區!$W$2:$W$2000, T32, 作業區!$X$2:$X$2000, U32)>0, "已存在", "未擴充") -> 已存在
A33: =ROW(A33)-1 -> 32 | B33: 地滑 | D33: 苗55鄉道遭土體掩埋 | E33: 苗栗縣 | F33: 卓蘭鎮 | G33: 上新里 | I33: 234379.95 | J33: 2689164 | K33: 233551 | L33: 2689370 | M33: 95 | N33: 0609豪雨 | O33: 38878.208 | P33: 1.滑動區房舍遭推擠錯動破壞。 2.苗55鄉道遭土體掩埋80公尺。 3.人命損失：0人 。4.房舍受損：13棟。5.農業損失：果園損失約2公頃。6.崩塌面積 2.0ha。 | R33: C1E510 | S33: 新開 | T33: 8.5 | U33: 286.7 | V33: 250 | W33: =IF(IF(ISERROR(SEARCH("-",P33))=TRUE,0,1)=1,IF(H33<>"",0,1),0) -> 0 | AC33: =IF(COUNTIFS(作業區!$W$2:$W$2000, T33, 作業區!$X$2:$X$2000, U33)>0, "已存在", "未擴充") -> 已存在
A34: =ROW(A34)-1 -> 33 | B34: 崩塌 | D34: 翠巒支線道路中斷 | E34: 南投縣 | F34: 仁愛鄉 | G34: 翠華村 | I34: 271788.82 | J34: 2676723.1 | K34: 270960 | L34: 2676929 | M34: 95 | N34: 0609豪雨 | O34: 38877.208 | P34: 1.力行產業道路翠巒支線遭受崩塌沖毀。2.民宅計有5棟沖毀。3.茶園林地約15公頃土地流失。4.電力設施電桿數十支沖毀。 | R34: 01H210 | S34: 翠巒 | T34: 25.5 | U34: 436.4 | V34: — | W34: =IF(IF(ISERROR(SEARCH("-",P34))=TRUE,0,1)=1,IF(H34<>"",0,1),0) -> 0 | AC34: =IF(COUNTIFS(作業區!$W$2:$W$2000, T34, 作業區!$X$2:$X$2000, U34)>0, "已存在", "未擴充") -> 已存在
A35: =ROW(A35)-1 -> 34 | B35: 崩塌 | D35: 47號民宅前 | E35: 南投縣 | F35: 信義鄉 | G35: 人和村 | I35: 239330.94 | J35: 2630325.3 | K35: 238502 | L35: 2630531 | M35: 95 | N35: 0609豪雨 | O35: 38877.208 | P35: 1.二戶民宅前空地及道路龜裂。2.民生巷道路中斷約100公尺、道路旁擋土牆約100公尺龜裂。3.人命損失：0人4.房舍受損：2棟。5.道路毀損：約100公尺。 | R35: C1I160 | S35: 龍神橋 | T35: 13.5 | U35: 71.3 | V35: — | W35: =IF(IF(ISERROR(SEARCH("-",P35))=TRUE,0,1)=1,IF(H35<>"",0,1),0) -> 0 | AC35: =IF(COUNTIFS(作業區!$W$2:$W$2000, T35, 作業區!$X$2:$X$2000, U35)>0, "已存在", "未擴充") -> 已存在
A36: =ROW(A36)-1 -> 35 | B36: 崩塌 | D36: 苗栗市新英里(台鐵台中線k145處) | E36: 苗栗縣 | F36: 苗栗市 | G36: 新英里 | I36: 229695.97 | J36: 2715188 | K36: 228867 | L36: 2715394 | M36: 95 | N36: 0609豪雨 | O36: 38878.333 | P36: 1.台鐵台中線k145處上邊坡崩塌破壞。2.鐵軌遭土石覆蓋50公尺。3.人命損失：輕傷6人。4.百餘列車誤點。5.崩塌面積0.13ha | R36: C1E550 | S36: 明德 | T36: 51 | U36: 261.6 | V36: — | W36: =IF(IF(ISERROR(SEARCH("-",P36))=TRUE,0,1)=1,IF(H36<>"",0,1),0) -> 0 | AC36: =IF(COUNTIFS(作業區!$W$2:$W$2000, T36, 作業區!$X$2:$X$2000, U36)>0, "已存在", "未擴充") -> 已存在
A37: =ROW(A37)-1 -> 36 | B37: 崩塌 | D37: 雲61線 | E37: 雲林縣 | F37: 林內鄉 | G37: 坪頂村 | I37: 213143.04 | J37: 2627780.3 | K37: 212314 | L37: 2627986 | M37: 95 | N37: 0609豪雨 | O37: 38877.708 | P37: 1.雲61線公路之坪頂村入口段路基邊坡土石崩塌約20公尺。2.人命損失：0人。3.倉庫受損：2棟。4.崩塌面積0.12ha。 | R37: 11H100 | S37: 竹山 | T37: 1 | U37: 250.7 | V37: — | W37: =IF(IF(ISERROR(SEARCH("-",P37))=TRUE,0,1)=1,IF(H37<>"",0,1),0) -> 0 | AC37: =IF(COUNTIFS(作業區!$W$2:$W$2000, T37, 作業區!$X$2:$X$2000, U37)>0, "已存在", "未擴充") -> 已存在
A38: =ROW(A38)-1 -> 37 | B38: 崩塌、地滑 | D38: 九號鄉道、台14線道路 | E38: 南投縣 | F38: 仁愛鄉 | G38: 大同村 | I38: 263296.85 | J38: 2657263.2 | K38: 262468 | L38: 2657469 | M38: 95 | N38: 0609豪雨 | O38: 38877.625 | P38: 1.九號鄉道中斷、建物基礎掏空。2.台14線道路龜裂，長約200m。3.人命損失：0人。 4. 房舍受損：18棟。5.擋土牆損壞約130公尺。 6. 九號鄉道崩塌範圍2.2ha。 | R38: 01H310 | S38: 翠峰 | T38: 9 | U38: 529.4 | V38: — | W38: =IF(IF(ISERROR(SEARCH("-",P38))=TRUE,0,1)=1,IF(H38<>"",0,1),0) -> 0 | AC38: =IF(COUNTIFS(作業區!$W$2:$W$2000, T38, 作業區!$X$2:$X$2000, U38)>0, "已存在", "未擴充") -> 已存在
A39: =ROW(A39)-1 -> 38 | B39: 地滑 | D39: 東勢鎮泰興里(石嵙巷) | E39: 臺中市 | F39: 東勢區 | G39: 泰興里 | I39: 227901.98 | J39: 2687192.1 | K39: 227073 | L39: 2687398 | M39: 96 | N39: 0604豪雨 | O39: 39241.583 | P39: 掩埋一輛行經石嵙巷之小客車。上邊坡之勝玄宮部分地基懸空。石嵙巷道路損毀約100公尺。人命損失：0人。房舍損失：1棟(勝玄宮) | R39: C1F920 | S39: 石岡 | T39: 20.5 | U39: 387.8 | V39: — | W39: =IF(IF(ISERROR(SEARCH("-",P39))=TRUE,0,1)=1,IF(H39<>"",0,1),0) -> 0 | AC39: =IF(COUNTIFS(作業區!$W$2:$W$2000, T39, 作業區!$X$2:$X$2000, U39)>0, "已存在", "未擴充") -> 已存在
A40: =ROW(A40)-1 -> 39 | B40: 地滑 | D40: 水里鄉車埕村(投131線29.1k處) | E40: 南投縣 | F40: 水里鄉 | G40: 車埕村 | I40: 235737.95 | J40: 2637144.2 | K40: 234909 | L40: 2637350 | M40: 96 | N40: 0604豪雨 | O40: 39240.667 | P40: 投131縣道中斷60m。檳榔樹坡面遭沖刷。無人傷亡及房屋受損。預力地錨式擋土牆偏移及下陷，長約60m。 | R40: C1I270 | S40: 水里 | T40: 30 | U40: 155.7 | V40: 250 | W40: =IF(IF(ISERROR(SEARCH("-",P40))=TRUE,0,1)=1,IF(H40<>"",0,1),0) -> 0 | AC40: =IF(COUNTIFS(作業區!$W$2:$W$2000, T40, 作業區!$X$2:$X$2000, U40)>0, "已存在", "未擴充") -> 已存在
A41: =ROW(A41)-1 -> 40 | B41: 崩塌 | D41: 石碇鄉潭邊村外石崁產業道路（縣106乙6.6k處） | E41: 新北市 | F41: 石碇區 | G41: 潭邊里 | I41: 315973.69 | J41: 2765877.8 | K41: 315145 | L41: 2766084 | M41: 96 | N41: 0604豪雨 | O41: 39241.375 | P41: 道路損毀：外石崁產業道路損毀約50公尺。人命損失：0人。民宅建物損毀：農舍乙棟。 | R41: C1A640 | S41: 石碇 | T41: 4.5 | U41: 230.3 | V41: 500 | W41: =IF(IF(ISERROR(SEARCH("-",P41))=TRUE,0,1)=1,IF(H41<>"",0,1),0) -> 0 | AC41: =IF(COUNTIFS(作業區!$W$2:$W$2000, T41, 作業區!$X$2:$X$2000, U41)>0, "已存在", "未擴充") -> 已存在
A42: =ROW(A42)-1 -> 41 | B42: 崩塌 | D42: 中和市華南里 | E42: 新北市 | F42: 中和區 | G42: 華南里 | I42: 301669.73 | J42: 2763844.8 | K42: 300841 | L42: 2764051 | M42: 96 | N42: 0604豪雨 | O42: 39243.25 | P42: 磐石樓外圍擋土牆遭受崩塌影響損毀。擋土牆約50公尺損壞。登山步道約15公尺斷裂。觀景魚池及涼亭一座損毀。 | R42: C1A700 | S42: 南勢角 | T42: 1 | U42: 232.6 | V42: — | W42: =IF(IF(ISERROR(SEARCH("-",P42))=TRUE,0,1)=1,IF(H42<>"",0,1),0) -> 0 | AC42: =IF(COUNTIFS(作業區!$W$2:$W$2000, T42, 作業區!$X$2:$X$2000, U42)>0, "已存在", "未擴充") -> 已存在
A43: =ROW(A43)-1 -> 42 | B43: 崩塌 | D43: 國姓鄉南港村(龍南道路4k處) | E43: 南投縣 | F43: 國姓鄉 | G43: 南港村 | I43: 234202.96 | J43: 2650392.2 | K43: 233374 | L43: 2650598 | M43: 96 | N43: 0604豪雨 | O43: 39240.667 | P43: 龍南道路中斷1250m。截水溝及集水井遭崩塌土石掩埋。無人傷亡集房屋受損。 | R43: C1I230 | S43: 九份二山 | T43: 26.5 | U43: 232.1 | V43: 250 | W43: =IF(IF(ISERROR(SEARCH("-",P43))=TRUE,0,1)=1,IF(H43<>"",0,1),0) -> 0 | AC43: =IF(COUNTIFS(作業區!$W$2:$W$2000, T43, 作業區!$X$2:$X$2000, U43)>0, "已存在", "未擴充") -> 已存在
A44: =ROW(A44)-1 -> 43 | B44: 崩塌 | D44: 安樂區三民里(麥金路) | E44: 基隆市 | F44: 安樂區 | G44: 三民里 | I44: 322735.67 | J44: 2779602.7 | K44: 321907 | L44: 2779809 | M44: 96 | N44: 0604豪雨 | O44: 39241.333 | P44: 崩塌土石約2000立方公尺，1輛廂型車、2輛小客車及1輛機車遭土石掩埋，造成3死4傷，麥金路中斷約50公尺。 | R44: 01B030 | S44: 五堵 | T44: 13 | U44: 192.9 | V44: — | W44: =IF(IF(ISERROR(SEARCH("-",P44))=TRUE,0,1)=1,IF(H44<>"",0,1),0) -> 0 | AC44: =IF(COUNTIFS(作業區!$W$2:$W$2000, T44, 作業區!$X$2:$X$2000, U44)>0, "已存在", "未擴充") -> 已存在
A45: =ROW(A45)-1 -> 44 | B45: 土石流 | D45: 太麻里鄉(加崙農路) | E45: 臺東縣 | F45: 太麻里鄉 | G45: 大王村 | H45: 東縣DF111 | I45: 249582.9 | J45: 2502786.8 | K45: 248754 | L45: 2502992 | M45: 96 | N45: 0809豪雨 | O45: 39303.083 | P45: 土石流流入民宅，漫淹道路。人命損失:0人。房舍受損:土石流入2戶。 | R45: C0S690 | S45: 太麻里 | T45: 55 | U45: 316.2 | V45: 450 | W45: =IF(IF(ISERROR(SEARCH("-",P45))=TRUE,0,1)=1,IF(H45<>"",0,1),0) -> 0 | AC45: =IF(COUNTIFS(作業區!$W$2:$W$2000, T45, 作業區!$X$2:$X$2000, U45)>0, "已存在", "未擴充") -> 已存在
...

Sheet 作業區
A1: 縣市 | B1: 鄉鎮區 | C1: 村里 | D1: 發生地點 | E1: 代表地標 | F1: 溪流型態(陳天健) | G1: 年度 | H1: 事件 | I1: 發生時間 | J1: 發生次數 | K1: 再發生時間間隔 | L1: 崩塌面積_災前 | M1: 崩塌面積_災後 | N1: 崩塌率_災前 | O1: 崩塌率_災後 | P1: 地震影響 | Q1: 發生次數(排除地震) | R1: 再發生時間間隔(排除地震) | S1: 警戒基準值 (mm) | T1: 觀測雨量站站號 | U1: 觀測雨量站站名 | V1: 事件總雨量 | W1: 發生降雨強度 | X1: 有效累積雨量 | Y1: 發生3小時 | Z1: 發生6小時 | AA1: 發生12小時 | AB1: 發生24小時 | AC1: 發生1hr重現期(年) | AD1: 發生3hr重現期(年) | AE1: 發生6hr重現期(年) | AF1: 發生12hr重現期(年) | AG1: 發生24hr重現期(年) | AH1: 雨場最大1小時 | AI1: 雨場最大3小時 | AJ1: 雨場最大6小時 | AK1: 雨場前最大12小時 | AL1: 雨場最大24小時 | AM1: 雨場1hr重現期(年) | AN1: 雨場3hr重現期(年) | AO1: 雨場6hr重現期(年) | AP1: 雨場12hr重現期(年) | AQ1: 雨場24hr重現期(年) | AR1: 發生降雨延時 | AS1: 崩塌面積 | AT1: 降雨強度 | AU1: 有效降雨量 | AV1: 類型
A2: 宜蘭縣 | B2: 南澳鄉 | C2: 碧候村 | D2: 宜縣DF146 | F2: 溪流型 | G2: 101 | H2: 蘇拉颱風 | I2: 41123.083 | J2: 1 | L2: 0.565 | M2: =IF(SUMIFS(水保局全省災害資料!$X:$X, 水保局全省災害資料!$E:$E, A2, 水保局全省災害資料!$F:$F, B2, 水保局全省災害資料!$N:$N, H2)=0, "", SUMIFS(水保局全省災害資料!$X:$X, 水保局全省災害資料!$E:$E, A2, 水保局全省災害資料!$F:$F, B2, 水保局全省災害資料!$N:$N, H2)) | N2: 0.30146196 | O2: 3.0599723 | P2: 否 | Q2: 1 | S2: 450 | T2: C0U770 | U2: 南澳 | V2: 878.5 | W2: 74.5 | X2: 668.9 | Y2: 158 | Z2: 259 | AA2: 333 | AB2: 442.5 | AC2: 2年 | AD2: 5年 | AE2: 10年 | AF2: 5年 | AG2: 5年 | AH2: 74.5 | AI2: 178 | AJ2: 300 | AK2: 433 | AL2: 582.5 | AM2: 2年 | AN2: 10年 | AO2: 25年 | AP2: 50年 | AQ2: 50年 | AR2: 59 | AS2: =IFERROR(INDEX(水保局全省災害資料!$X$2:$X$2000, MATCH(1, INDEX((水保局全省災害資料!$T$2:$T$2000=W2)*(水保局全省災害資料!$U$2:$U$2000=X2), 0, 1), 0)), "") -> 0 | AT2: =IFERROR(INDEX(水保局全省災害資料!$T$2:$T$2000, MATCH(1, INDEX((水保局全省災害資料!$T$2:$T$2000=W2)*(水保局全省災害資料!$U$2:$U$2000=X2), 0, 1), 0)), "") -> 74.5 | AU2: =IFERROR(INDEX(水保局全省災害資料!$U$2:$U$2000, MATCH(1, INDEX((水保局全省災害資料!$T$2:$T$2000=W2)*(水保局全省災害資料!$U$2:$U$2000=X2), 0, 1), 0)), "") -> 668.9 | AV2: =IFERROR(INDEX(水保局全省災害資料!$B$2:$B$2000, MATCH(1, INDEX((水保局全省災害資料!$T$2:$T$2000=W2)*(水保局全省災害資料!$U$2:$U$2000=X2), 0, 1), 0)), "") -> 土石流
A3: 宜蘭縣 | B3: 南澳鄉 | C3: 碧候村 | D3: 宜縣DF146 | F3: 溪流型 | G3: 113 | H3: 凱米颱風 | I3: 45498.042 | J3: 2 | K3: 11.986187 | L3: 0 | M3: =IF(SUMIFS(水保局全省災害資料!$X:$X, 水保局全省災害資料!$E:$E, A3, 水保局全省災害資料!$F:$F, B3, 水保局全省災害資料!$N:$N, H3)=0, "", SUMIFS(水保局全省災害資料!$X:$X, 水保局全省災害資料!$E:$E, A3, 水保局全省災害資料!$F:$F, B3, 水保局全省災害資料!$N:$N, H3)) | N3: 0 | O3: 2.4917298 | P3: 是 | S3: 400 | T3: 81U860 | U3: 金岳國小 | V3: 810 | W3: 53.5 | X3: 742.2 | Y3: 82.5 | Z3: 133 | AA3: 519.5 | AB3: 707 | AC3: <2 | AD3: <2 | AE3: <2 | AF3: 200年 | AG3: 200年 | AH3: 95.5 | AI3: 266 | AJ3: 392 | AK3: 524 | AL3: 707 | AM3: 10年 | AN3: 200年 | AO3: 200年 | AP3: 200年 | AQ3: 200年 | AR3: 39 | AS3: =IFERROR(INDEX(水保局全省災害資料!$X$2:$X$2000, MATCH(1, INDEX((水保局全省災害資料!$T$2:$T$2000=W3)*(水保局全省災害資料!$U$2:$U$2000=X3), 0, 1), 0)), "") -> 0 | AT3: =IFERROR(INDEX(水保局全省災害資料!$T$2:$T$2000, MATCH(1, INDEX((水保局全省災害資料!$T$2:$T$2000=W3)*(水保局全省災害資料!$U$2:$U$2000=X3), 0, 1), 0)), "") -> 53.5 | AU3: =IFERROR(INDEX(水保局全省災害資料!$U$2:$U$2000, MATCH(1, INDEX((水保局全省災害資料!$T$2:$T$2000=W3)*(水保局全省災害資料!$U$2:$U$2000=X3), 0, 1), 0)), "") -> 742.2 | AV3: =IFERROR(INDEX(水保局全省災害資料!$B$2:$B$2000, MATCH(1, INDEX((水保局全省災害資料!$T$2:$T$2000=W3)*(水保局全省災害資料!$U$2:$U$2000=X3), 0, 1), 0)), "") -> 土石流
A4: 南投縣 | B4: 仁愛鄉 | C4: 南豐村 | D4: 投縣DF011 | F4: 溪流型 | G4: 97 | H4: 辛樂克颱風 | I4: 39706.208 | J4: 3 | K4: 4.2060502 | L4: 0 | M4: =IF(SUMIFS(水保局全省災害資料!$X:$X, 水保局全省災害資料!$E:$E, A4, 水保局全省災害資料!$F:$F, B4, 水保局全省災害資料!$N:$N, H4)=0, "", SUMIFS(水保局全省災害資料!$X:$X, 水保局全省災害資料!$E:$E, A4, 水保局全省災害資料!$F:$F, B4, 水保局全省災害資料!$N:$N, H4)) | N4: 0 | O4: 0 | P4: 否 | Q4: 1 | S4: 250 | T4: C1I330 | U4: 楓樹林 | V4: 1211 | W4: 44.5 | X4: 737.4 | Y4: 104 | Z4: 157.5 | AA4: 264 | AB4: 640 | AC4: <2 | AD4: <2 | AE4: <2 | AF4: 2年 | AG4: 50年 | AH4: 69.5 | AI4: 186 | AJ4: 341 | AK4: 582.5 | AL4: 838.5 | AM4: 2年 | AN4: 10年 | AO4: 100年 | AP4: 200年 | AQ4: 200年 | AR4: 35 | AS4: =IFERROR(INDEX(水保局全省災害資料!$X$2:$X$2000, MATCH(1, INDEX((水保局全省災害資料!$T$2:$T$2000=W4)*(水保局全省災害資料!$U$2:$U$2000=X4), 0, 1), 0)), "") -> 0 | AT4: =IFERROR(INDEX(水保局全省災害資料!$T$2:$T$2000, MATCH(1, INDEX((水保局全省災害資料!$T$2:$T$2000=W4)*(水保局全省災害資料!$U$2:$U$2000=X4), 0, 1), 0)), "") -> 44.5 | AU4: =IFERROR(INDEX(水保局全省災害資料!$U$2:$U$2000, MATCH(1, INDEX((水保局全省災害資料!$T$2:$T$2000=W4)*(水保局全省災害資料!$U$2:$U$2000=X4), 0, 1), 0)), "") -> 737.4 | AV4: =IFERROR(INDEX(水保局全省災害資料!$B$2:$B$2000, MATCH(1, INDEX((水保局全省災害資料!$T$2:$T$2000=W4)*(水保局全省災害資料!$U$2:$U$2000=X4), 0, 1), 0)), "") -> 土石流
A5: 南投縣 | B5: 仁愛鄉 | C5: 南豐村 | D5: 投縣DF011 | F5: 溪流型 | G5: 112 | H5: 卡努颱風 | I5: 45142.708 | J5: 4 | K5: 14.894521 | L5: 0 | M5: =IF(SUMIFS(水保局全省災害資料!$X:$X, 水保局全省災害資料!$E:$E, A5, 水保局全省災害資料!$F:$F, B5, 水保局全省災害資料!$N:$N, H5)=0, "", SUMIFS(水保局全省災害資料!$X:$X, 水保局全省災害資料!$E:$E, A5, 水保局全省災害資料!$F:$F, B5, 水保局全省災害資料!$N:$N, H5)) -> 7.0375 | N5: 0 | O5: 0.50539084 | P5: 否 | Q5: 2 | R5: 14.894521 | S5: 300 | T5: 88H890 | U5: 南豐 | V5: 864 | W5: 112 | X5: 782 | Y5: 225 | Z5: 384 | AA5: 542 | AB5: 783.5 | AC5: 100年 | AD5: 100年 | AE5: 200年 | AF5: 200年 | AG5: 200年 | AH5: 112.5 | AI5: 225 | AJ5: 384 | AK5: 542 | AL5: 783.5 | AM5: 100年 | AN5: 100年 | AO5: 200年 | AP5: 200年 | AQ5: 200年 | AR5: 39 | AS5: =IFERROR(INDEX(水保局全省災害資料!$X$2:$X$2000, MATCH(1, INDEX((水保局全省災害資料!$T$2:$T$2000=W5)*(水保局全省災害資料!$U$2:$U$2000=X5), 0, 1), 0)), "") -> 0.3 | AT5: =IFERROR(INDEX(水保局全省災害資料!$T$2:$T$2000, MATCH(1, INDEX((水保局全省災害資料!$T$2:$T$2000=W5)*(水保局全省災害資料!$U$2:$U$2000=X5), 0, 1), 0)), "") -> 112 | AU5: =IFERROR(INDEX(水保局全省災害資料!$U$2:$U$2000, MATCH(1, INDEX((水保局全省災害資料!$T$2:$T$2000=W5)*(水保局全省災害資料!$U$2:$U$2000=X5), 0, 1), 0)), "") -> 782 | AV5: =IFERROR(INDEX(水保局全省災害資料!$B$2:$B$2000, MATCH(1, INDEX((水保局全省災害資料!$T$2:$T$2000=W5)*(水保局全省災害資料!$U$2:$U$2000=X5), 0, 1), 0)), "") -> 土石流
A6: 南投縣 | B6: 仁愛鄉 | C6: 南豐村 | D6: 投縣DF013 | E6: 聖本篤加油站 | F6: 溪流型 | G6: 97 | H6: 辛樂克颱風 | I6: 39706.333 | J6: 3 | K6: 4.2063927 | L6: 0 | M6: =IF(SUMIFS(水保局全省災害資料!$X:$X, 水保局全省災害資料!$E:$E, A6, 水保局全省災害資料!$F:$F, B6, 水保局全省災害資料!$N:$N, H6)=0, "", SUMIFS(水保局全省災害資料!$X:$X, 水保局全省災害資料!$E:$E, A6, 水保局全省災害資料!$F:$F, B6, 水保局全省災害資料!$N:$N, H6)) | N6: 0 | O6: 0.23443605 | P6: 否 | Q6: 1 | S6: 300 | T6: C1I330 | U6: 楓樹林 | V6: 1211 | W6: 55.5 | X6: 917.8 | Y6: 186 | Z6: 290 | AA6: 377 | AB6: 762 | AC6: <2 | AD6: 10年 | AE6: 25年 | AF6: 10年 | AG6: 200年 | AH6: 69.5 | AI6: 186 | AJ6: 341 | AK6: 582.5 | AL6: 838.5 | AM6: 2年 | AN6: 10年 | AO6: 100年 | AP6: 200年 | AQ6: 200年 | AR6: 38 | AS6: =IFERROR(INDEX(水保局全省災害資料!$X$2:$X$2000, MATCH(1, INDEX((水保局全省災害資料!$T$2:$T$2000=W6)*(水保局全省災害資料!$U$2:$U$2000=X6), 0, 1), 0)), "") -> 0 | AT6: =IFERROR(INDEX(水保局全省災害資料!$T$2:$T$2000, MATCH(1, INDEX((水保局全省災害資料!$T$2:$T$2000=W6)*(水保局全省災害資料!$U$2:$U$2000=X6), 0, 1), 0)), "") -> 55.5 | AU6: =IFERROR(INDEX(水保局全省災害資料!$U$2:$U$2000, MATCH(1, INDEX((水保局全省災害資料!$T$2:$T$2000=W6)*(水保局全省災害資料!$U$2:$U$2000=X6), 0, 1), 0)), "") -> 917.8 | AV6: =IFERROR(INDEX(水保局全省災害資料!$B$2:$B$2000, MATCH(1, INDEX((水保局全省災害資料!$T$2:$T$2000=W6)*(水保局全省災害資料!$U$2:$U$2000=X6), 0, 1), 0)), "") -> 土石流
A7: 南投縣 | B7: 仁愛鄉 | C7: 南豐村 | D7: 投縣DF013 | E7: 聖本篤加油站 | F7: 溪流型 | G7: 112 | H7: 卡努颱風 | I7: 45142.625 | J7: 4 | K7: 14.89395 | L7: 0 | M7: =IF(SUMIFS(水保局全省災害資料!$X:$X, 水保局全省災害資料!$E:$E, A7, 水保局全省災害資料!$F:$F, B7, 水保局全省災害資料!$N:$N, H7)=0, "", SUMIFS(水保局全省災害資料!$X:$X, 水保局全省災害資料!$E:$E, A7, 水保局全省災害資料!$F:$F, B7, 水保局全省災害資料!$N:$N, H7)) -> 7.0375 | N7: 0 | O7: 0 | P7: 否 | Q7: 2 | R7: 14.89395 | S7: 300 | T7: 88H890 | U7: 南豐 | V7: 864 | W7: 49 | X7: 648 | Y7: 115 | Z7: 260.5 | AA7: 425.5 | AB7: 628 | AC7: <2 | AD7: <2 | AE7: 25年 | AF7: 100年 | AG7: 200年 | AH7: 112.5 | AI7: 225 | AJ7: 384 | AK7: 542 | AL7: 783.5 | AM7: 100年 | AN7: 100年 | AO7: 200年 | AP7: 200年 | AQ7: 200年 | AR7: 37 | AS7: =IFERROR(INDEX(水保局全省災害資料!$X$2:$X$2000, MATCH(1, INDEX((水保局全省災害資料!$T$2:$T$2000=W7)*(水保局全省災害資料!$U$2:$U$2000=X7), 0, 1), 0)), "") -> - | AT7: =IFERROR(INDEX(水保局全省災害資料!$T$2:$T$2000, MATCH(1, INDEX((水保局全省災害資料!$T$2:$T$2000=W7)*(水保局全省災害資料!$U$2:$U$2000=X7), 0, 1), 0)), "") -> 49 | AU7: =IFERROR(INDEX(水保局全省災害資料!$U$2:$U$2000, MATCH(1, INDEX((水保局全省災害資料!$T$2:$T$2000=W7)*(水保局全省災害資料!$U$2:$U$2000=X7), 0, 1), 0)), "") -> 648 | AV7: =IFERROR(INDEX(水保局全省災害資料!$B$2:$B$2000, MATCH(1, INDEX((水保局全省災害資料!$T$2:$T$2000=W7)*(水保局全省災害資料!$U$2:$U$2000=X7), 0, 1), 0)), "") -> 土石流
A8: 南投縣 | B8: 仁愛鄉 | C8: 春陽村 | D8: 投縣DF030 | F8: 溪流型 | G8: 112 | H8: 卡努颱風 | I8: 45143.417 | J8: 2 | K8: 18.056393 | L8: 0 | M8: =IF(SUMIFS(水保局全省災害資料!$X:$X, 水保局全省災害資料!$E:$E, A8, 水保局全省災害資料!$F:$F, B8, 水保局全省災害資料!$N:$N, H8)=0, "", SUMIFS(水保局全省災害資料!$X:$X, 水保局全省災害資料!$E:$E, A8, 水保局全省災害資料!$F:$F, B8, 水保局全省災害資料!$N:$N, H8)) -> 7.0375 | N8: 0 | O8: 0.12039731 | P8: 否 | Q8: 2 | R8: 18.056393 | S8: 300 | T8: C0I010 | U8: 廬山 | V8: 792.5 | W8: 6 | X8: 695 | Y8: 34.5 | Z8: 34.5 | AA8: 46 | AB8: 445 | AC8: <2 | AD8: <2 | AE8: <2 | AF8: <2 | AG8: 5年 | AH8: 89.5 | AI8: 247 | AJ8: 334.5 | AK8: 529.5 | AL8: 710 | AM8: 10年 | AN8: 100年 | AO8: 100年 | AP8: 200年 | AQ8: 200年 | AR8: 42 | AS8: =IFERROR(INDEX(水保局全省災害資料!$X$2:$X$2000, MATCH(1, INDEX((水保局全省災害資料!$T$2:$T$2000=W8)*(水保局全省災害資料!$U$2:$U$2000=X8), 0, 1), 0)), "") -> 0.12 | AT8: =IFERROR(INDEX(水保局全省災害資料!$T$2:$T$2000, MATCH(1, INDEX((水保局全省災害資料!$T$2:$T$2000=W8)*(水保局全省災害資料!$U$2:$U$2000=X8), 0, 1), 0)), "") -> 6 | AU8: =IFERROR(INDEX(水保局全省災害資料!$U$2:$U$2000, MATCH(1, INDEX((水保局全省災害資料!$T$2:$T$2000=W8)*(水保局全省災害資料!$U$2:$U$2000=X8), 0, 1), 0)), "") -> 695 | AV8: =IFERROR(INDEX(水保局全省災害資料!$B$2:$B$2000, MATCH(1, INDEX((水保局全省災害資料!$T$2:$T$2000=W8)*(水保局全省災害資料!$U$2:$U$2000=X8), 0, 1), 0)), "") -> 土石流 、崩塌 (山崩 )
A9: 南投縣 | B9: 水里鄉 | C9: 上安村 | D9: 投縣DF165 | E9: 三部坑溪 | F9: 溪流型 | G9: 95 | H9: 0609豪雨 | I9: 38878.5 | J9: 4 | K9: 0.84657534 | L9: 1.63 | M9: =IF(SUMIFS(水保局全省災害資料!$X:$X, 水保局全省災害資料!$E:$E, A9, 水保局全省災害資料!$F:$F, B9, 水保局全省災害資料!$N:$N, H9)=0, "", SUMIFS(水保局全省災害資料!$X:$X, 水保局全省災害資料!$E:$E, A9, 水保局全省災害資料!$F:$F, B9, 水保局全省災害資料!$N:$N, H9)) | N9: 0.47890469 | O9: 1.4690328 | P9: 否 | Q9: 2 | R9: 0.84657534 | S9: 200 | T9: C1I160 | U9: 龍神橋 | V9: 445.5 | W9: 3.5 | X9: 401.6 | Y9: 24 | Z9: 93 | AA9: 138 | AB9: 263 | AC9: <2 | AD9: <2 | AE9: <2 | AF9: <2 | AG9: <2 | AH9: 41 | AI9: 83 | AJ9: 139 | AK9: 196.5 | AL9: 309 | AM9: <2 | AN9: <2 | AO9: <2 | AP9: <2 | AQ9: 2年 | AR9: 33 | AS9: =IFERROR(INDEX(水保局全省災害資料!$X$2:$X$2000, MATCH(1, INDEX((水保局全省災害資料!$T$2:$T$2000=W9)*(水保局全省災害資料!$U$2:$U$2000=X9), 0, 1), 0)), "") -> 0 | AT9: =IFERROR(INDEX(水保局全省災害資料!$T$2:$T$2000, MATCH(1, INDEX((水保局全省災害資料!$T$2:$T$2000=W9)*(水保局全省災害資料!$U$2:$U$2000=X9), 0, 1), 0)), "") -> 3.5 | AU9: =IFERROR(INDEX(水保局全省災害資料!$U$2:$U$2000, MATCH(1, INDEX((水保局全省災害資料!$T$2:$T$2000=W9)*(水保局全省災害資料!$U$2:$U$2000=X9), 0, 1), 0)), "") -> 401.6 | AV9: =IFERROR(INDEX(水保局全省災害資料!$B$2:$B$2000, MATCH(1, INDEX((水保局全省災害資料!$T$2:$T$2000=W9)*(水保局全省災害資料!$U$2:$U$2000=X9), 0, 1), 0)), "") -> 土石流
A10: 南投縣 | B10: 信義鄉 | C10: 潭南村 | D10: 投縣DF178 | E10: 潭南一號橋 | F10: 溪流型 | G10: 97 | H10: 卡玫基颱風 | I10: 39647.083 | J10: 2 | K10: 6.9721461 | L10: 0 | M10: =IF(SUMIFS(水保局全省災害資料!$X:$X, 水保局全省災害資料!$E:$E, A10, 水保局全省災害資料!$F:$F, B10, 水保局全省災害資料!$N:$N, H10)=0, "", SUMIFS(水保局全省災害資料!$X:$X, 水保局全省災害資料!$E:$E, A10, 水保局全省災害資料!$F:$F, B10, 水保局全省災害資料!$N:$N, H10)) | N10: 0 | O10: 0.51039556 | P10: 否 | Q10: 1 | S10: 250 | T10: C1I150 | U10: 青雲 | V10: 404 | W10: 109 | X10: 272.6 | Y10: 212.5 | Z10: 234 | AA10: 242 | AB10: 242 | AC10: 50年 | AD10: 50年 | AE10: 10年 | AF10: 2年 | AG10: <2 | AH10: 108 | AI10: 222.5 | AJ10: 309 | AK10: 376 | AL10: 404 | AM10: 50年 | AN10: 100年 | AO10: 50年 | AP10: 25年 | AQ10: 5年 | AR10: 11 | AS10: =IFERROR(INDEX(水保局全省災害資料!$X$2:$X$2000, MATCH(1, INDEX((水保局全省災害資料!$T$2:$T$2000=W10)*(水保局全省災害資料!$U$2:$U$2000=X10), 0, 1), 0)), "") -> 0 | AT10: =IFERROR(INDEX(水保局全省災害資料!$T$2:$T$2000, MATCH(1, INDEX((水保局全省災害資料!$T$2:$T$2000=W10)*(水保局全省災害資料!$U$2:$U$2000=X10), 0, 1), 0)), "") -> 109 | AU10: =IFERROR(INDEX(水保局全省災害資料!$U$2:$U$2000, MATCH(1, INDEX((水保局全省災害資料!$T$2:$T$2000=W10)*(水保局全省災害資料!$U$2:$U$2000=X10), 0, 1), 0)), "") -> 272.6 | AV10: =IFERROR(INDEX(水保局全省災害資料!$B$2:$B$2000, MATCH(1, INDEX((水保局全省災害資料!$T$2:$T$2000=W10)*(水保局全省災害資料!$U$2:$U$2000=X10), 0, 1), 0)), "") -> 土石流
A11: 南投縣 | B11: 信義鄉 | C11: 明德村 | D11: 投縣DF187 | F11: 坡面型 | G11: 113 | H11: 凱米颱風 | I11: 45498.125 | J11: 2 | K11: 23.002283 | L11: 0 | M11: =IF(SUMIFS(水保局全省災害資料!$X:$X, 水保局全省災害資料!$E:$E, A11, 水保局全省災害資料!$F:$F, B11, 水保局全省災害資料!$N:$N, H11)=0, "", SUMIFS(水保局全省災害資料!$X:$X, 水保局全省災害資料!$E:$E, A11, 水保局全省災害資料!$F:$F, B11, 水保局全省災害資料!$N:$N, H11)) | N11: 0 | O11: 0 | P11: 否 | Q11: 1 | S11: 300 | T11: C0I080 | U11: 信義 | V11: 613.5 | W11: 52.5 | X11: 336.5 | Y11: 148 | Z11: 193.5 | AA11: 297 | AB11: 337.5 | AC11: <2 | AD11: 5年 | AE11: 5年 | AF11: 10年 | AG11: 2年 | AH11: 53 | AI11: 148.5 | AJ11: 231 | AK11: 332.5 | AL11: 526.5 | AM11: <2 | AN11: 5年 | AO11: 10年 | AP11: 25年 | AQ11: 100年 | AR11: 38 | AS11: =IFERROR(INDEX(水保局全省災害資料!$X$2:$X$2000, MATCH(1, INDEX((水保局全省災害資料!$T$2:$T$2000=W11)*(水保局全省災害資料!$U$2:$U$2000=X11), 0, 1), 0)), "") -> 0 | AT11: =IFERROR(INDEX(水保局全省災害資料!$T$2:$T$2000, MATCH(1, INDEX((水保局全省災害資料!$T$2:$T$2000=W11)*(水保局全省災害資料!$U$2:$U$2000=X11), 0, 1), 0)), "") -> 52.5 | AU11: =IFERROR(INDEX(水保局全省災害資料!$U$2:$U$2000, MATCH(1, INDEX((水保局全省災害資料!$T$2:$T$2000=W11)*(水保局全省災害資料!$U$2:$U$2000=X11), 0, 1), 0)), "") -> 336.5 | AV11: =IFERROR(INDEX(水保局全省災害資料!$B$2:$B$2000, MATCH(1, INDEX((水保局全省災害資料!$T$2:$T$2000=W11)*(水保局全省災害資料!$U$2:$U$2000=X11), 0, 1), 0)), "") -> 土石流
A12: 南投縣 | B12: 信義鄉 | C12: 豐丘村 | D12: 投縣DF189 | E12: 豐丘明隧道 | F12: 溪流型 | G12: 97 | H12: 辛樂克颱風 | I12: 39706.792 | J12: 3 | K12: 7.1364155 | L12: 0.84 | M12: =IF(SUMIFS(水保局全省災害資料!$X:$X, 水保局全省災害資料!$E:$E, A12, 水保局全省災害資料!$F:$F, B12, 水保局全省災害資料!$N:$N, H12)=0, "", SUMIFS(水保局全省災害資料!$X:$X, 水保局全省災害資料!$E:$E, A12, 水保局全省災害資料!$F:$F, B12, 水保局全省災害資料!$N:$N, H12)) | N12: 0.44766574 | O12: 0.30910254 | P12: 否 | Q12: 1 | S12: 250 | T12: C1I080 | U12: 信義 | V12: 598 | W12: 2.5 | X12: 552.5 | Y12: 6 | Z12: 12 | AA12: 30.5 | AB12: 30.5 | AC12: <2 | AD12: <2 | AE12: <2 | AF12: <2 | AG12: <2 | AH12: 43 | AI12: 118 | AJ12: 197 | AK12: 296.5 | AL12: 475 | AM12: <2 | AN12: 2年 | AO12: 5年 | AP12: 10年 | AQ12: 25年 | AR12: 38 | AS12: =IFERROR(INDEX(水保局全省災害資料!$X$2:$X$2000, MATCH(1, INDEX((水保局全省災害資料!$T$2:$T$2000=W12)*(水保局全省災害資料!$U$2:$U$2000=X12), 0, 1), 0)), "") -> 0 | AT12: =IFERROR(INDEX(水保局全省災害資料!$T$2:$T$2000, MATCH(1, INDEX((水保局全省災害資料!$T$2:$T$2000=W12)*(水保局全省災害資料!$U$2:$U$2000=X12), 0, 1), 0)), "") -> 2.5 | AU12: =IFERROR(INDEX(水保局全省災害資料!$U$2:$U$2000, MATCH(1, INDEX((水保局全省災害資料!$T$2:$T$2000=W12)*(水保局全省災害資料!$U$2:$U$2000=X12), 0, 1), 0)), "") -> 552.5 | AV12: =IFERROR(INDEX(水保局全省災害資料!$B$2:$B$2000, MATCH(1, INDEX((水保局全省災害資料!$T$2:$T$2000=W12)*(水保局全省災害資料!$U$2:$U$2000=X12), 0, 1), 0)), "") -> 土石流、崩塌
A13: 南投縣 | B13: 信義鄉 | C13: 豐丘村 | D13: 投縣DF190 | E13: 豐丘 | F13: 溪流型 | G13: 101 | H13: 0504豪雨 | I13: 41032.667 | J13: 3 | K13: 10.76895 | L13: 1.62 | M13: =IF(SUMIFS(水保局全省災害資料!$X:$X, 水保局全省災害資料!$E:$E, A13, 水保局全省災害資料!$F:$F, B13, 水保局全省災害資料!$N:$N, H13)=0, "", SUMIFS(水保局全省災害資料!$X:$X, 水保局全省災害資料!$E:$E, A13, 水保局全省災害資料!$F:$F, B13, 水保局全省災害資料!$N:$N, H13)) | N13: 1.0074 | O13: 1.3245445 | P13: 否 | Q13: 1 | S13: 250 | T13: C1I290 | U13: 豐丘 | V13: 138 | W13: 38.5 | X13: 121.4 | Y13: 92 | Z13: 138 | AA13: 138 | AB13: 138 | AC13: <2 | AD13: <2 | AE13: <2 | AF13: <2 | AG13: <2 | AH13: 46.5 | AI13: 92 | AJ13: 138 | AK13: 138 | AL13: 138 | AM13: <2 | AN13: <2 | AO13: <2 | AP13: <2 | AQ13: <2 | AR13: 138 | AS13: =IFERROR(INDEX(水保局全省災害資料!$X$2:$X$2000, MATCH(1, INDEX((水保局全省災害資料!$T$2:$T$2000=W13)*(水保局全省災害資料!$U$2:$U$2000=X13), 0, 1), 0)), "") -> 0 | AT13: =IFERROR(INDEX(水保局全省災害資料!$T$2:$T$2000, MATCH(1, INDEX((水保局全省災害資料!$T$2:$T$2000=W13)*(水保局全省災害資料!$U$2:$U$2000=X13), 0, 1), 0)), "") -> 38.5 | AU13: =IFERROR(INDEX(水保局全省災害資料!$U$2:$U$2000, MATCH(1, INDEX((水保局全省災害資料!$T$2:$T$2000=W13)*(水保局全省災害資料!$U$2:$U$2000=X13), 0, 1), 0)), "") -> 121.4 | AV13: =IFERROR(INDEX(水保局全省災害資料!$B$2:$B$2000, MATCH(1, INDEX((水保局全省災害資料!$T$2:$T$2000=W13)*(水保局全省災害資料!$U$2:$U$2000=X13), 0, 1), 0)), "") -> 土石流
A14: 南投縣 | B14: 信義鄉 | C14: 神木村 | D14: 投縣DF199 | E14: 出水溪 | F14: 溪流型 | G14: 98 | H14: 莫拉克颱風 | I14: 40033.625 | J14: 6 | K14: 5.1058219 | L14: 57.6 | M14: =IF(SUMIFS(水保局全省災害資料!$X:$X, 水保局全省災害資料!$E:$E, A14, 水保局全省災害資料!$F:$F, B14, 水保局全省災害資料!$N:$N, H14)=0, "", SUMIFS(水保局全省災害資料!$X:$X, 水保局全省災害資料!$E:$E, A14, 水保局全省災害資料!$F:$F, B14, 水保局全省災害資料!$N:$N, H14)) | N14: 6.8166487 | O14: 8.6687416 | P14: 否 | Q14: 1 | S14: 250 | T14: C0H9A0 | U14: 神木村 | V14: 1919 | W14: 34 | X14: 576.1 | Y14: 91.5 | Z14: 152 | AA14: 289.5 | AB14: 423 | AC14: <2 | AD14: <2 | AE14: <2 | AF14: 2年 | AG14: 2年 | AH14: 95 | AI14: 255.5 | AJ14: 392 | AK14: 653 | AL14: 1138.5 | AM14: 10年 | AN14: 100年 | AO14: 200年 | AP14: 200年 | AQ14: 200年 | AR14: 39 | AS14: =IFERROR(INDEX(水保局全省災害資料!$X$2:$X$2000, MATCH(1, INDEX((水保局全省災害資料!$T$2:$T$2000=W14)*(水保局全省災害資料!$U$2:$U$2000=X14), 0, 1), 0)), "") -> 0 | AT14: =IFERROR(INDEX(水保局全省災害資料!$T$2:$T$2000, MATCH(1, INDEX((水保局全省災害資料!$T$2:$T$2000=W14)*(水保局全省災害資料!$U$2:$U$2000=X14), 0, 1), 0)), "") -> 34 | AU14: =IFERROR(INDEX(水保局全省災害資料!$U$2:$U$2000, MATCH(1, INDEX((水保局全省災害資料!$T$2:$T$2000=W14)*(水保局全省災害資料!$U$2:$U$2000=X14), 0, 1), 0)), "") -> 576.1 | AV14: =IFERROR(INDEX(水保局全省災害資料!$B$2:$B$2000, MATCH(1, INDEX((水保局全省災害資料!$T$2:$T$2000=W14)*(水保局全省災害資料!$U$2:$U$2000=X14), 0, 1), 0)), "") -> 土石流
A15: 南投縣 | B15: 信義鄉 | C15: 神木村 | D15: 投縣DF200 | E15: 舊愛玉橋 | F15: 溪流型 | G15: 98 | H15: 莫拉克颱風 | I15: 40033.875 | J15: 2 | K15: 8.0317352 | L15: 0 | M15: =IF(SUMIFS(水保局全省災害資料!$X:$X, 水保局全省災害資料!$E:$E, A15, 水保局全省災害資料!$F:$F, B15, 水保局全省災害資料!$N:$N, H15)=0, "", SUMIFS(水保局全省災害資料!$X:$X, 水保局全省災害資料!$E:$E, A15, 水保局全省災害資料!$F:$F, B15, 水保局全省災害資料!$N:$N, H15)) | N15: 0 | O15: 1.4848035 | P15: 否 | Q15: 1 | S15: 250 | T15: C0H9A0 | U15: 神木村 | V15: 1919 | W15: 38 | X15: 786.9 | Y15: 122.5 | Z15: 240.5 | AA15: 392.5 | AB15: 604.5 | AC15: <2 | AD15: <2 | AE15: 5年 | AF15: 10年 | AG15: 25年 | AH15: 95 | AI15: 255.5 | AJ15: 392 | AK15: 653 | AL15: 1138.5 | AM15: 10年 | AN15: 100年 | AO15: 200年 | AP15: 200年 | AQ15: 200年 | AR15: 45 | AS15: =IFERROR(INDEX(水保局全省災害資料!$X$2:$X$2000, MATCH(1, INDEX((水保局全省災害資料!$T$2:$T$2000=W15)*(水保局全省災害資料!$U$2:$U$2000=X15), 0, 1), 0)), "") -> 0 | AT15: =IFERROR(INDEX(水保局全省災害資料!$T$2:$T$2000, MATCH(1, INDEX((水保局全省災害資料!$T$2:$T$2000=W15)*(水保局全省災害資料!$U$2:$U$2000=X15), 0, 1), 0)), "") -> 38 | AU15: =IFERROR(INDEX(水保局全省災害資料!$U$2:$U$2000, MATCH(1, INDEX((水保局全省災害資料!$T$2:$T$2000=W15)*(水保局全省災害資料!$U$2:$U$2000=X15), 0, 1), 0)), "") -> 786.9 | AV15: =IFERROR(INDEX(水保局全省災害資料!$B$2:$B$2000, MATCH(1, INDEX((水保局全省災害資料!$T$2:$T$2000=W15)*(水保局全省災害資料!$U$2:$U$2000=X15), 0, 1), 0)), "") -> 土石流
A16: 南投縣 | B16: 信義鄉 | C16: 同富村 | D16: 投縣DF202 | E16: 頭坑橋 | F16: 溪流型 | G16: 98 | H16: 莫拉克颱風 | I16: 40034.083 | J16: 2 | K16: 8.033105 | L16: 0 | M16: =IF(SUMIFS(水保局全省災害資料!$X:$X, 水保局全省災害資料!$E:$E, A16, 水保局全省災害資料!$F:$F, B16, 水保局全省災害資料!$N:$N, H16)=0, "", SUMIFS(水保局全省災害資料!$X:$X, 水保局全省災害資料!$E:$E, A16, 水保局全省災害資料!$F:$F, B16, 水保局全省災害資料!$N:$N, H16)) | N16: 0 | O16: 5.0452452 | P16: 否 | Q16: 1 | S16: 250 | T16: C0H9A0 | U16: 神木村 | V16: 1919 | W16: 89 | X16: 1087.9 | Y16: 226.5 | Z16: 349 | AA16: 585.5 | AB16: 857 | AC16: 5年 | AD16: 50年 | AE16: 50年 | AF16: 200年 | AG16: 200年 | AH16: 95 | AI16: 255.5 | AJ16: 392 | AK16: 653 | AL16: 1138.5 | AM16: 10年 | AN16: 100年 | AO16: 200年 | AP16: 200年 | AQ16: 200年 | AR16: 49 | AS16: =IFERROR(INDEX(水保局全省災害資料!$X$2:$X$2000, MATCH(1, INDEX((水保局全省災害資料!$T$2:$T$2000=W16)*(水保局全省災害資料!$U$2:$U$2000=X16), 0, 1), 0)), "") -> 0 | AT16: =IFERROR(INDEX(水保局全省災害資料!$T$2:$T$2000, MATCH(1, INDEX((水保局全省災害資料!$T$2:$T$2000=W16)*(水保局全省災害資料!$U$2:$U$2000=X16), 0, 1), 0)), "") -> 89 | AU16: =IFERROR(INDEX(水保局全省災害資料!$U$2:$U$2000, MATCH(1, INDEX((水保局全省災害資料!$T$2:$T$2000=W16)*(水保局全省災害資料!$U$2:$U$2000=X16), 0, 1), 0)), "") -> 1087.9 | AV16: =IFERROR(INDEX(水保局全省災害資料!$B$2:$B$2000, MATCH(1, INDEX((水保局全省災害資料!$T$2:$T$2000=W16)*(水保局全省災害資料!$U$2:$U$2000=X16), 0, 1), 0)), "") -> 土石流、洪水
A17: 南投縣 | B17: 信義鄉 | C17: 同富村 | D17: 投縣DF202 | E17: 頭坑橋 | F17: 溪流型 | G17: 101 | H17: 0610豪雨 | I17: 41071.792 | J17: 3 | K17: 2.8430365 | L17: 22.2 | M17: =IF(SUMIFS(水保局全省災害資料!$X:$X, 水保局全省災害資料!$E:$E, A17, 水保局全省災害資料!$F:$F, B17, 水保局全省災害資料!$N:$N, H17)=0, "", SUMIFS(水保局全省災害資料!$X:$X, 水保局全省災害資料!$E:$E, A17, 水保局全省災害資料!$F:$F, B17, 水保局全省災害資料!$N:$N, H17)) | N17: 5.1378185 | O17: 4.1843135 | P17: 否 | Q17: 2 | R17: 2.8430365 | S17: 250 | T17: C1I340 | U17: 新興橋 | V17: 656.5 | W17: 18.5 | X17: 434.8 | Y17: 59 | Z17: 129 | AA17: 237.5 | AB17: 307 | AC17: <2 | AD17: <2 | AE17: <2 | AF17: <2 | AG17: <2 | AH17: 32 | AI17: 80.5 | AJ17: 150.5 | AK17: 244 | AL17: 353 | AM17: <2 | AN17: <2 | AO17: <2 | AP17: 2年 | AQ17: 2年 | AR17: 40 | AS17: =IFERROR(INDEX(水保局全省災害資料!$X$2:$X$2000, MATCH(1, INDEX((水保局全省災害資料!$T$2:$T$2000=W17)*(水保局全省災害資料!$U$2:$U$2000=X17), 0, 1), 0)), "") -> 0 | AT17: =IFERROR(INDEX(水保局全省災害資料!$T$2:$T$2000, MATCH(1, INDEX((水保局全省災害資料!$T$2:$T$2000=W17)*(水保局全省災害資料!$U$2:$U$2000=X17), 0, 1), 0)), "") -> 18.5 | AU17: =IFERROR(INDEX(水保局全省災害資料!$U$2:$U$2000, MATCH(1, INDEX((水保局全省災害資料!$T$2:$T$2000=W17)*(水保局全省災害資料!$U$2:$U$2000=X17), 0, 1), 0)), "") -> 434.8 | AV17: =IFERROR(INDEX(水保局全省災害資料!$B$2:$B$2000, MATCH(1, INDEX((水保局全省災害資料!$T$2:$T$2000=W17)*(水保局全省災害資料!$U$2:$U$2000=X17), 0, 1), 0)), "") -> 土石流、洪水(土砂淤積)
A18: 南投縣 | B18: 信義鄉 | C18: 東埔村 | D18: 投縣DF206 | E18: 東埔溫泉 | F18: 溪流型 | G18: 112 | H18: 一般降雨 | I18: 45162.708 | J18: 1 | L18: 0 | M18: =IF(SUMIFS(水保局全省災害資料!$X:$X, 水保局全省災害資料!$E:$E, A18, 水保局全省災害資料!$F:$F, B18, 水保局全省災害資料!$N:$N, H18)=0, "", SUMIFS(水保局全省災害資料!$X:$X, 水保局全省災害資料!$E:$E, A18, 水保局全省災害資料!$F:$F, B18, 水保局全省災害資料!$N:$N, H18)) | N18: 0 | O18: 0 | P18: 否 | Q18: 1 | S18: 300 | T18: C1I070 | U18: 和社 | V18: 42 | W18: 29 | X18: 46 | Y18: 36.5 | Z18: 36.5 | AA18: 36.5 | AB18: 36.5 | AC18: <2 | AD18: <2 | AE18: <2 | AF18: <2 | AG18: <2 | AH18: 29 | AI18: 42 | AJ18: 42 | AK18: 42 | AL18: 42 | AM18: <2 | AN18: <2 | AO18: <2 | AP18: <2 | AQ18: <2 | AR18: 3 | AS18: =IFERROR(INDEX(水保局全省災害資料!$X$2:$X$2000, MATCH(1, INDEX((水保局全省災害資料!$T$2:$T$2000=W18)*(水保局全省災害資料!$U$2:$U$2000=X18), 0, 1), 0)), "") | AT18: =IFERROR(INDEX(水保局全省災害資料!$T$2:$T$2000, MATCH(1, INDEX((水保局全省災害資料!$T$2:$T$2000=W18)*(水保局全省災害資料!$U$2:$U$2000=X18), 0, 1), 0)), "") | AU18: =IFERROR(INDEX(水保局全省災害資料!$U$2:$U$2000, MATCH(1, INDEX((水保局全省災害資料!$T$2:$T$2000=W18)*(水保局全省災害資料!$U$2:$U$2000=X18), 0, 1), 0)), "") | AV18: =IFERROR(INDEX(水保局全省災害資料!$B$2:$B$2000, MATCH(1, INDEX((水保局全省災害資料!$T$2:$T$2000=W18)*(水保局全省災害資料!$U$2:$U$2000=X18), 0, 1), 0)), "")
A19: 南投縣 | B19: 信義鄉 | C19: 東埔村 | D19: 投縣DF206 | E19: 東埔溫泉 | F19: 溪流型 | G19: 113 | H19: 一般降雨 | I19: 45440.5 | J19: 2 | K19: 0.76107306 | L19: 0.1 | M19: =IF(SUMIFS(水保局全省災害資料!$X:$X, 水保局全省災害資料!$E:$E, A19, 水保局全省災害資料!$F:$F, B19, 水保局全省災害資料!$N:$N, H19)=0, "", SUMIFS(水保局全省災害資料!$X:$X, 水保局全省災害資料!$E:$E, A19, 水保局全省災害資料!$F:$F, B19, 水保局全省災害資料!$N:$N, H19)) | N19: 0.12410027 | O19: -2146826273 | P19: 否 | Q19: 2 | R19: 0.76107306 | S19: 300 | T19: 01H400 | U19: 東埔 | V19: 41 | W19: 18 | X19: 102 | Y19: 48.5 | Z19: 57.5 | AA19: 60 | AB19: 67 | AC19: <2 | AD19: <2 | AE19: <2 | AF19: <2 | AG19: <2 | AH19: 14 | AI19: 32 | AJ19: 41 | AK19: 41 | AL19: 41 | AM19: <2 | AN19: <2 | AO19: <2 | AP19: <2 | AQ19: <2 | AR19: 6 | AS19: =IFERROR(INDEX(水保局全省災害資料!$X$2:$X$2000, MATCH(1, INDEX((水保局全省災害資料!$T$2:$T$2000=W19)*(水保局全省災害資料!$U$2:$U$2000=X19), 0, 1), 0)), "") | AT19: =IFERROR(INDEX(水保局全省災害資料!$T$2:$T$2000, MATCH(1, INDEX((水保局全省災害資料!$T$2:$T$2000=W19)*(水保局全省災害資料!$U$2:$U$2000=X19), 0, 1), 0)), "") | AU19: =IFERROR(INDEX(水保局全省災害資料!$U$2:$U$2000, MATCH(1, INDEX((水保局全省災害資料!$T$2:$T$2000=W19)*(水保局全省災害資料!$U$2:$U$2000=X19), 0, 1), 0)), "") | AV19: =IFERROR(INDEX(水保局全省災害資料!$B$2:$B$2000, MATCH(1, INDEX((水保局全省災害資料!$T$2:$T$2000=W19)*(水保局全省災害資料!$U$2:$U$2000=X19), 0, 1), 0)), "")
